Workbook

Sheet Paper_1
A1: Asset | B1: Threat type | C1: Security Attribute | D1: Damage Scenario | E1: Attack Path | F1: Attack vector | G1: Attack Vector Note / Motiv | H1: Safety Impact | I1: Safety Note / Motiv | J1: Financial Impact | K1: Financial Note / Motiv | L1: Operational Impact | M1: Operational Note / Motiv | N1: Privacy and Legislative Impact | O1: Privacy Note / Motiv | P1: Severity Level | Q1: Feasibility Level | R1: Risk Value | S1: Treatment Options | T1: Measures | U1: Affected Design Elements | V1: Justification (Treatment) | W1: Cybersecurity Goals | Y1: s | Z1: f | AA1: o | AB1: p | AC1: impact | AD1: feasibility val | AE1: Risk score
A2: T-01 - PM2.5 measurement | B2: Spoofing | C2: Integrity, Authenticity | D2: Incorrectly low PM2.5 values can cause a false indication of acceptable particulate exposure. | E2: PM2.5 Sensor → IUC → telemetry → user/status display | F2: Local | G2: Attack requires local access to the sensor-to-IUC measurement interface to inject or manipulate readings. | H2: Moderate | I2: A false low particulate reading can contribute to an incorrect exposure assessment; the PDF identifies incorrect PM2.5 exposure indication as a relevant damage. | J2: Negligible | K2: The source describes an environmental-monitoring consequence without a direct financial loss mechanism. | L2: Moderate | M2: The monitoring function can provide incorrect air-quality information and degrade environmental decision-making. | N2: Negligible | O2: PM2.5 telemetry is not identified in the source as inherently privacy-sensitive or directly linked to a person. | P2: =IF(AC2>=Reference!$H$2, Reference!$G$2, IF(AC2>=Reference!$H$3, Reference!$G$3, IF(AC2>=Reference!$H$4, Reference!$G$4, IF(AC2>=Reference!$H$5, Reference!$G$5, "")))) -> Major | Q2: =IF(F2="Physical", "Very Low", IF(F2="Local", "Low", IF(F2="Adjacent", "Medium", IF(F2="Network", "High", "")))) -> Low | R2: =IF(AE2>=Reference!$D$2, Reference!$G$2, IF(AE2>=Reference!$D$3, Reference!$E$3, IF(AE2>=Reference!$D$4, Reference!$E$4, IF(AE2>=Reference!$D$5, Reference!$E$5, "")))) -> Medium | S2: Risk Reduction | T2: Sensor message authentication, integrity checks, plausibility/range checks, anomaly detection, secure calibration, replay protection | U2: PM2.5 sensor interface; IUC sensor-ingestion function; telemetry processing; user/status presentation | V2: Reduce the chance that fabricated sensor values are accepted as genuine measurements by enforcing authenticity and integrity at ingestion. | W2: Ensure PM2.5 measurement integrity and authenticity from sensor to alarm/monitoring consumer. | Y2: =IF(H2=Reference!$A$12, Reference!$C$12, IF(H2=Reference!$A$11, Reference!$C$11, IF(H2=Reference!$A$10, Reference!$C$10, IF(H2=Reference!$A$9, Reference!$C$9, 0)))) -> 4 | Z2: =IF(J2=Reference!$A$20, Reference!$C$20, IF(J2=Reference!$A$19, Reference!$C$19, IF(J2=Reference!$A$18, Reference!$C$18, IF(J2=Reference!$A$17, Reference!$C$17, 0)))) -> 1 | AA2: =IF(L2=Reference!$A$28, Reference!$C$28, IF(L2=Reference!$A$27, Reference!$C$27, IF(L2=Reference!$A$26, Reference!$C$26, IF(L2=Reference!$A$25, Reference!$C$25, 0)))) -> 4 | AB2: =IF(N2=Reference!$A$36, Reference!$C$36, IF(N2=Reference!$A$35, Reference!$C$35, IF(N2=Reference!$A$34, Reference!$C$34, IF(N2=Reference!$A$33, Reference!$C$33, 0)))) -> 1 | AC2: =(Reference!$B$2*Y2 + Reference!$B$3*AA2 + Reference!$B$4*Z2 + Reference!$B$5*AB2)/4 -> 6.1875 | AD2: =IF(Q2=Reference!$C$41, Reference!$D$41, IF(Q2=Reference!$C$42, Reference!$D$42, IF(Q2=Reference!$C$43, Reference!$D$43, IF(Q2=Reference!$C$44, Reference!$D$44, 0)))) -> 4 | AE2: =1+(AC2*AD2) -> 25.75
A3: T-02 - PM10 measurement | B3: Spoofing | C3: Integrity, Authenticity | D3: False PM10 measurements can produce an incorrect particulate-exposure indication and mask elevated concentrations. | E3: PM10 Sensor → IUC → telemetry → user/status display | F3: Physical | G3: The PDF explicitly cites physical access to the sensor communication path as a way to supply false measurements. | H3: Moderate | I3: Incorrect PM10 values can contribute to an incorrect exposure assessment; the source lists PM2.5/PM10 measurement integrity as a key asset. | J3: Negligible | K3: No specific direct financial damage is identified in the source for this sensor-level manipulation. | L3: Moderate | M3: Incorrect measurements impair the environmental-monitoring function and can affect air-quality decisions. | N3: Negligible | O3: The source does not identify PM10 data as privacy-sensitive by itself. | P3: =IF(AC3>=Reference!$H$2, Reference!$G$2, IF(AC3>=Reference!$H$3, Reference!$G$3, IF(AC3>=Reference!$H$4, Reference!$G$4, IF(AC3>=Reference!$H$5, Reference!$G$5, "")))) -> Major | Q3: =IF(F3="Physical", "Very Low", IF(F3="Local", "Low", IF(F3="Adjacent", "Medium", IF(F3="Network", "High", "")))) -> Very Low | R3: =IF(AE3>=Reference!$D$2, Reference!$G$2, IF(AE3>=Reference!$D$3, Reference!$E$3, IF(AE3>=Reference!$D$4, Reference!$E$4, IF(AE3>=Reference!$D$5, Reference!$E$5, "")))) -> Low | S3: Risk Reduction | T3: Authenticated sensor messaging, physical interface protection, plausibility checks, calibration controls, anomaly detection | U3: PM10 sensor; sensor bus/interface; IUC sensor ingestion; downstream telemetry consumers | V3: Protect the local sensor interface and validate readings before they enter trusted processing. | W3: Ensure PM10 measurement integrity and authenticity; reject implausible or unauthenticated values. | Y3: =IF(H3=Reference!$A$12, Reference!$C$12, IF(H3=Reference!$A$11, Reference!$C$11, IF(H3=Reference!$A$10, Reference!$C$10, IF(H3=Reference!$A$9, Reference!$C$9, 0)))) -> 4 | Z3: =IF(J3=Reference!$A$20, Reference!$C$20, IF(J3=Reference!$A$19, Reference!$C$19, IF(J3=Reference!$A$18, Reference!$C$18, IF(J3=Reference!$A$17, Reference!$C$17, 0)))) -> 1 | AA3: =IF(L3=Reference!$A$28, Reference!$C$28, IF(L3=Reference!$A$27, Reference!$C$27, IF(L3=Reference!$A$26, Reference!$C$26, IF(L3=Reference!$A$25, Reference!$C$25, 0)))) -> 4 | AB3: =IF(N3=Reference!$A$36, Reference!$C$36, IF(N3=Reference!$A$35, Reference!$C$35, IF(N3=Reference!$A$34, Reference!$C$34, IF(N3=Reference!$A$33, Reference!$C$33, 0)))) -> 1 | AC3: =(Reference!$B$2*Y3 + Reference!$B$3*AA3 + Reference!$B$4*Z3 + Reference!$B$5*AB3)/4 -> 6.1875 | AD3: =IF(Q3=Reference!$C$41, Reference!$D$41, IF(Q3=Reference!$C$42, Reference!$D$42, IF(Q3=Reference!$C$43, Reference!$D$43, IF(Q3=Reference!$C$44, Reference!$D$44, 0)))) -> 1 | AE3: =1+(AC3*AD3) -> 7.1875
A4: T-03 - CO measurement and alarm state | B4: Spoofing | C4: Integrity, Authenticity | D4: A genuine high-CO condition may be represented as low CO, suppressing a hazardous-gas warning and creating a false-safe indication. | E4: CO Sensor → IUC → Wi-Fi/LoRa → Edge → Cloud → User / Status Display | F4: Local | G4: An attacker injects a counterfeit CO measurement at or before IUC ingestion so the trusted path carries a false low value. | H4: Major | I4: The PDF identifies false-negative CO detection as a high-consequence scenario that can expose occupants to hazardous CO without warning. | J4: Moderate | K4: A missed hazardous condition can trigger incident response, liability, service, or remediation costs. | L4: Major | M4: A false-negative alarm can impair an important monitoring function by preventing timely hazard detection. | N4: Negligible | O4: The threat concerns measurement integrity; no direct privacy effect is identified. | P4: =IF(AC4>=Reference!$H$2, Reference!$G$2, IF(AC4>=Reference!$H$3, Reference!$G$3, IF(AC4>=Reference!$H$4, Reference!$G$4, IF(AC4>=Reference!$H$5, Reference!$G$5, "")))) -> Severe | Q4: =IF(F4="Physical", "Very Low", IF(F4="Local", "Low", IF(F4="Adjacent", "Medium", IF(F4="Network", "High", "")))) -> Low | R4: =IF(AE4>=Reference!$D$2, Reference!$G$2, IF(AE4>=Reference!$D$3, Reference!$E$3, IF(AE4>=Reference!$D$4, Reference!$E$4, IF(AE4>=Reference!$D$5, Reference!$E$5, "")))) -> Medium | S4: Risk Reduction | T4: Strong sensor authentication, signed/MACed measurements, freshness protection, plausibility/cross-sensor checks, alarm-state validation | U4: CO sensor; IUC ingestion; Wi-Fi/LoRa paths; Far/LoRa Edge; cloud alarm-processing; Status Display | V4: The source prioritizes authenticity + freshness + integrity of the physical measurement all the way to the alarm consumer. | W4: Prevent false CO measurements from suppressing required alarms; preserve end-to-end authenticity, freshness and integrity. | Y4: =IF(H4=Reference!$A$12, Reference!$C$12, IF(H4=Reference!$A$11, Reference!$C$11, IF(H4=Reference!$A$10, Reference!$C$10, IF(H4=Reference!$A$9, Reference!$C$9, 0)))) -> 7 | Z4: =IF(J4=Reference!$A$20, Reference!$C$20, IF(J4=Reference!$A$19, Reference!$C$19, IF(J4=Reference!$A$18, Reference!$C$18, IF(J4=Reference!$A$17, Reference!$C$17, 0)))) -> 4 | AA4: =IF(L4=Reference!$A$28, Reference!$C$28, IF(L4=Reference!$A$27, Reference!$C$27, IF(L4=Reference!$A$26, Reference!$C$26, IF(L4=Reference!$A$25, Reference!$C$25, 0)))) -> 7 | AB4: =IF(N4=Reference!$A$36, Reference!$C$36, IF(N4=Reference!$A$35, Reference!$C$35, IF(N4=Reference!$A$34, Reference!$C$34, IF(N4=Reference!$A$33, Reference!$C$33, 0)))) -> 1 | AC4: =(Reference!$B$2*Y4 + Reference!$B$3*AA4 + Reference!$B$4*Z4 + Reference!$B$5*AB4)/4 -> 11.0625 | AD4: =IF(Q4=Reference!$C$41, Reference!$D$41, IF(Q4=Reference!$C$42, Reference!$D$42, IF(Q4=Reference!$C$43, Reference!$D$43, IF(Q4=Reference!$C$44, Reference!$D$44, 0)))) -> 4 | AE4: =1+(AC4*AD4) -> 45.25
A5: T-04 - CO measurement, alarm threshold/status | B5: Tampering | C5: Integrity | D5: Changing CO measurements or alarm-threshold/status data can suppress, delay, or misclassify a hazardous-gas alarm. | E5: CO Sensor → IUC; manipulated value/threshold → alarm logic | F5: Local | G5: Sensor data or threshold-related values are altered before reaching the IUC or alarm-processing function. | H5: Major | I5: A manipulated threshold or CO value can create a false-negative hazard condition similar to the source's CO damage chain. | J5: Moderate | K5: Incorrect alarm behavior can create response, maintenance, and liability costs. | L5: Major | M5: The monitoring/alarm function can be materially impaired by persistent threshold or status manipulation. | N5: Negligible | O5: No direct privacy consequence is identified for this measurement/threshold attack. | P5: =IF(AC5>=Reference!$H$2, Reference!$G$2, IF(AC5>=Reference!$H$3, Reference!$G$3, IF(AC5>=Reference!$H$4, Reference!$G$4, IF(AC5>=Reference!$H$5, Reference!$G$5, "")))) -> Severe | Q5: =IF(F5="Physical", "Very Low", IF(F5="Local", "Low", IF(F5="Adjacent", "Medium", IF(F5="Network", "High", "")))) -> Low | R5: =IF(AE5>=Reference!$D$2, Reference!$G$2, IF(AE5>=Reference!$D$3, Reference!$E$3, IF(AE5>=Reference!$D$4, Reference!$E$4, IF(AE5>=Reference!$D$5, Reference!$E$5, "")))) -> Medium | S5: Risk Reduction | T5: Signed configuration, secure parameter storage, threshold authorization, integrity checks, change logging, plausibility monitoring | U5: CO sensor; calibration/threshold configuration; IUC alarm logic; Status Display | V5: Treat thresholds and alarm state as security-critical configuration, not only as ordinary sensor data. | W5: Protect CO alarm thresholds and status against unauthorized modification; detect and reject altered values. | Y5: =IF(H5=Reference!$A$12, Reference!$C$12, IF(H5=Reference!$A$11, Reference!$C$11, IF(H5=Reference!$A$10, Reference!$C$10, IF(H5=Reference!$A$9, Reference!$C$9, 0)))) -> 7 | Z5: =IF(J5=Reference!$A$20, Reference!$C$20, IF(J5=Reference!$A$19, Reference!$C$19, IF(J5=Reference!$A$18, Reference!$C$18, IF(J5=Reference!$A$17, Reference!$C$17, 0)))) -> 4 | AA5: =IF(L5=Reference!$A$28, Reference!$C$28, IF(L5=Reference!$A$27, Reference!$C$27, IF(L5=Reference!$A$26, Reference!$C$26, IF(L5=Reference!$A$25, Reference!$C$25, 0)))) -> 7 | AB5: =IF(N5=Reference!$A$36, Reference!$C$36, IF(N5=Reference!$A$35, Reference!$C$35, IF(N5=Reference!$A$34, Reference!$C$34, IF(N5=Reference!$A$33, Reference!$C$33, 0)))) -> 1 | AC5: =(Reference!$B$2*Y5 + Reference!$B$3*AA5 + Reference!$B$4*Z5 + Reference!$B$5*AB5)/4 -> 11.0625 | AD5: =IF(Q5=Reference!$C$41, Reference!$D$41, IF(Q5=Reference!$C$42, Reference!$D$42, IF(Q5=Reference!$C$43, Reference!$D$43, IF(Q5=Reference!$C$44, Reference!$D$44, 0)))) -> 4 | AE5: =1+(AC5*AD5) -> 45.25
A6: T-05 - CO2 measurement | B6: Spoofing | C6: Integrity, Authenticity | D6: False CO2 values can cause incorrect ventilation or indoor-air-quality decisions. | E6: CO2 Sensor → IUC → telemetry → user/status display | F6: Local | G6: Counterfeit CO2 measurements are supplied to the IUC so the monitoring function reports an incorrect concentration. | H6: Moderate | I6: The source identifies incorrect CO2 information as a consequential environmental/ventilation damage. | J6: Negligible | K6: The source does not identify a specific direct financial loss for this sensor-level spoofing. | L6: Moderate | M6: Incorrect CO2 information can partially degrade the environmental-monitoring and ventilation-decision function. | N6: Negligible | O6: CO2 concentration data is not described as directly privacy-sensitive. | P6: =IF(AC6>=Reference!$H$2, Reference!$G$2, IF(AC6>=Reference!$H$3, Reference!$G$3, IF(AC6>=Reference!$H$4, Reference!$G$4, IF(AC6>=Reference!$H$5, Reference!$G$5, "")))) -> Major | Q6: =IF(F6="Physical", "Very Low", IF(F6="Local", "Low", IF(F6="Adjacent", "Medium", IF(F6="Network", "High", "")))) -> Low | R6: =IF(AE6>=Reference!$D$2, Reference!$G$2, IF(AE6>=Reference!$D$3, Reference!$E$3, IF(AE6>=Reference!$D$4, Reference!$E$4, IF(AE6>=Reference!$D$5, Reference!$E$5, "")))) -> Medium | S6: Risk Reduction | T6: Sensor authentication, integrity protection, plausibility checks, anomaly detection, calibration controls | U6: CO2 sensor; IUC ingestion; telemetry pipeline; dashboard/status output | V6: Validate CO2 readings before using them in ventilation or air-quality decisions. | W6: Maintain authentic, integrity-protected CO2 measurements through monitoring and presentation. | Y6: =IF(H6=Reference!$A$12, Reference!$C$12, IF(H6=Reference!$A$11, Reference!$C$11, IF(H6=Reference!$A$10, Reference!$C$10, IF(H6=Reference!$A$9, Reference!$C$9, 0)))) -> 4 | Z6: =IF(J6=Reference!$A$20, Reference!$C$20, IF(J6=Reference!$A$19, Reference!$C$19, IF(J6=Reference!$A$18, Reference!$C$18, IF(J6=Reference!$A$17, Reference!$C$17, 0)))) -> 1 | AA6: =IF(L6=Reference!$A$28, Reference!$C$28, IF(L6=Reference!$A$27, Reference!$C$27, IF(L6=Reference!$A$26, Reference!$C$26, IF(L6=Reference!$A$25, Reference!$C$25, 0)))) -> 4 | AB6: =IF(N6=Reference!$A$36, Reference!$C$36, IF(N6=Reference!$A$35, Reference!$C$35, IF(N6=Reference!$A$34, Reference!$C$34, IF(N6=Reference!$A$33, Reference!$C$33, 0)))) -> 1 | AC6: =(Reference!$B$2*Y6 + Reference!$B$3*AA6 + Reference!$B$4*Z6 + Reference!$B$5*AB6)/4 -> 6.1875 | AD6: =IF(Q6=Reference!$C$41, Reference!$D$41, IF(Q6=Reference!$C$42, Reference!$D$42, IF(Q6=Reference!$C$43, Reference!$D$43, IF(Q6=Reference!$C$44, Reference!$D$44, 0)))) -> 4 | AE6: =1+(AC6*AD6) -> 25.75
A7: T-06 - NO2 measurement | B7: Spoofing | C7: Integrity, Authenticity | D7: False low NO2 measurements can suppress detection of toxic-pollutant exposure. | E7: NO2 Sensor → IUC → Wi-Fi/LoRa → Edge → Cloud → User / Status Display | F7: Local | G7: The attacker supplies artificially low or otherwise false NO2 measurements to the IUC. | H7: Major | I7: The source identifies false-negative NO2 detection as an undetected toxic-pollutant exposure scenario. | J7: Moderate | K7: Missed exposure can lead to incident response, remediation, service, or liability costs. | L7: Major | M7: An important environmental hazard-monitoring function is degraded when toxic exposure is not detected. | N7: Negligible | O7: No direct privacy effect is identified for NO2 measurements. | P7: =IF(AC7>=Reference!$H$2, Reference!$G$2, IF(AC7>=Reference!$H$3, Reference!$G$3, IF(AC7>=Reference!$H$4, Reference!$G$4, IF(AC7>=Reference!$H$5, Reference!$G$5, "")))) -> Severe | Q7: =IF(F7="Physical", "Very Low", IF(F7="Local", "Low", IF(F7="Adjacent", "Medium", IF(F7="Network", "High", "")))) -> Low | R7: =IF(AE7>=Reference!$D$2, Reference!$G$2, IF(AE7>=Reference!$D$3, Reference!$E$3, IF(AE7>=Reference!$D$4, Reference!$E$4, IF(AE7>=Reference!$D$5, Reference!$E$5, "")))) -> Medium | S7: Risk Reduction | T7: Sensor authentication, end-to-end integrity, freshness checks, plausibility/anomaly detection, alarm-state validation | U7: NO2 sensor; IUC ingestion; both telemetry paths; edge/cloud alarm processing; user/status display | V7: The source calls out authenticity, freshness and integrity of physical measurements through to the alarm consumer. | W7: Prevent suppression of NO2 hazard detection; preserve authentic, fresh and integral measurements end-to-end. | Y7: =IF(H7=Reference!$A$12, Reference!$C$12, IF(H7=Reference!$A$11, Reference!$C$11, IF(H7=Reference!$A$10, Reference!$C$10, IF(H7=Reference!$A$9, Reference!$C$9, 0)))) -> 7 | Z7: =IF(J7=Reference!$A$20, Reference!$C$20, IF(J7=Reference!$A$19, Reference!$C$19, IF(J7=Reference!$A$18, Reference!$C$18, IF(J7=Reference!$A$17, Reference!$C$17, 0)))) -> 4 | AA7: =IF(L7=Reference!$A$28, Reference!$C$28, IF(L7=Reference!$A$27, Reference!$C$27, IF(L7=Reference!$A$26, Reference!$C$26, IF(L7=Reference!$A$25, Reference!$C$25, 0)))) -> 7 | AB7: =IF(N7=Reference!$A$36, Reference!$C$36, IF(N7=Reference!$A$35, Reference!$C$35, IF(N7=Reference!$A$34, Reference!$C$34, IF(N7=Reference!$A$33, Reference!$C$33, 0)))) -> 1 | AC7: =(Reference!$B$2*Y7 + Reference!$B$3*AA7 + Reference!$B$4*Z7 + Reference!$B$5*AB7)/4 -> 11.0625 | AD7: =IF(Q7=Reference!$C$41, Reference!$D$41, IF(Q7=Reference!$C$42, Reference!$D$42, IF(Q7=Reference!$C$43, Reference!$D$43, IF(Q7=Reference!$C$44, Reference!$D$44, 0)))) -> 4 | AE7: =1+(AC7*AD7) -> 45.25
A8: T-07 - SO2 measurement | B8: Spoofing | C8: Integrity, Authenticity | D8: False low SO2 measurements can suppress detection of toxic-pollutant exposure. | E8: SO2 Sensor → IUC → Wi-Fi/LoRa → Edge → Cloud → User / Status Display | F8: Local | G8: False SO2 sensor values are presented to the IUC so the monitoring function reports an incorrect concentration. | H8: Major | I8: The source identifies false-negative SO2 detection as an undetected toxic-pollutant exposure scenario. | J8: Moderate | K8: Missed exposure can create response, remediation, service, or liability costs. | L8: Major | M8: Toxic-pollutant monitoring can be materially impaired when SO2 alarms are suppressed. | N8: Negligible | O8: No direct privacy effect is identified for SO2 measurements. | P8: =IF(AC8>=Reference!$H$2, Reference!$G$2, IF(AC8>=Reference!$H$3, Reference!$G$3, IF(AC8>=Reference!$H$4, Reference!$G$4, IF(AC8>=Reference!$H$5, Reference!$G$5, "")))) -> Severe | Q8: =IF(F8="Physical", "Very Low", IF(F8="Local", "Low", IF(F8="Adjacent", "Medium", IF(F8="Network", "High", "")))) -> Low | R8: =IF(AE8>=Reference!$D$2, Reference!$G$2, IF(AE8>=Reference!$D$3, Reference!$E$3, IF(AE8>=Reference!$D$4, Reference!$E$4, IF(AE8>=Reference!$D$5, Reference!$E$5, "")))) -> Medium | S8: Risk Reduction | T8: Authenticated sensor data, end-to-end integrity and freshness, anomaly detection, plausibility checks, alarm validation | U8: SO2 sensor; IUC ingestion; telemetry paths; edge/cloud processing; user/status display | V8: Protect SO2 measurement authenticity and freshness through all trusted processing points. | W8: Prevent false-negative SO2 detection; preserve integrity, authenticity and freshness. | Y8: =IF(H8=Reference!$A$12, Reference!$C$12, IF(H8=Reference!$A$11, Reference!$C$11, IF(H8=Reference!$A$10, Reference!$C$10, IF(H8=Reference!$A$9, Reference!$C$9, 0)))) -> 7 | Z8: =IF(J8=Reference!$A$20, Reference!$C$20, IF(J8=Reference!$A$19, Reference!$C$19, IF(J8=Reference!$A$18, Reference!$C$18, IF(J8=Reference!$A$17, Reference!$C$17, 0)))) -> 4 | AA8: =IF(L8=Reference!$A$28, Reference!$C$28, IF(L8=Reference!$A$27, Reference!$C$27, IF(L8=Reference!$A$26, Reference!$C$26, IF(L8=Reference!$A$25, Reference!$C$25, 0)))) -> 7 | AB8: =IF(N8=Reference!$A$36, Reference!$C$36, IF(N8=Reference!$A$35, Reference!$C$35, IF(N8=Reference!$A$34, Reference!$C$34, IF(N8=Reference!$A$33, Reference!$C$33, 0)))) -> 1 | AC8: =(Reference!$B$2*Y8 + Reference!$B$3*AA8 + Reference!$B$4*Z8 + Reference!$B$5*AB8)/4 -> 11.0625 | AD8: =IF(Q8=Reference!$C$41, Reference!$D$41, IF(Q8=Reference!$C$42, Reference!$D$42, IF(Q8=Reference!$C$43, Reference!$D$43, IF(Q8=Reference!$C$44, Reference!$D$44, 0)))) -> 4 | AE8: =1+(AC8*AD8) -> 45.25
A9: T-08 - O3 measurement | B9: Spoofing | C9: Integrity, Authenticity | D9: False low ozone measurements can suppress detection of toxic-pollutant exposure. | E9: O3 Sensor → IUC → Wi-Fi/LoRa → Edge → Cloud → User / Status Display | F9: Local | G9: Counterfeit ozone concentration data is injected into the monitoring path. | H9: Major | I9: The source identifies false-negative O3 detection as an undetected toxic-pollutant exposure scenario. | J9: Moderate | K9: Missed exposure can create response, remediation, service, or liability costs. | L9: Major | M9: The hazard-monitoring function can be materially impaired by suppressed O3 detection. | N9: Negligible | O9: No direct privacy effect is identified for O3 measurements. | P9: =IF(AC9>=Reference!$H$2, Reference!$G$2, IF(AC9>=Reference!$H$3, Reference!$G$3, IF(AC9>=Reference!$H$4, Reference!$G$4, IF(AC9>=Reference!$H$5, Reference!$G$5, "")))) -> Severe | Q9: =IF(F9="Physical", "Very Low", IF(F9="Local", "Low", IF(F9="Adjacent", "Medium", IF(F9="Network", "High", "")))) -> Low | R9: =IF(AE9>=Reference!$D$2, Reference!$G$2, IF(AE9>=Reference!$D$3, Reference!$E$3, IF(AE9>=Reference!$D$4, Reference!$E$4, IF(AE9>=Reference!$D$5, Reference!$E$5, "")))) -> Medium | S9: Risk Reduction | T9: Sensor authentication, signed/MACed data, freshness protection, anomaly detection, plausibility and alarm checks | U9: O3 sensor; IUC ingestion; Wi-Fi/LoRa paths; edge/cloud alarm processing; display | V9: Apply the same end-to-end protection emphasized by the source for toxic-pollutant measurements. | W9: Prevent false-negative ozone detection; maintain authentic, fresh and integral measurements. | Y9: =IF(H9=Reference!$A$12, Reference!$C$12, IF(H9=Reference!$A$11, Reference!$C$11, IF(H9=Reference!$A$10, Reference!$C$10, IF(H9=Reference!$A$9, Reference!$C$9, 0)))) -> 7 | Z9: =IF(J9=Reference!$A$20, Reference!$C$20, IF(J9=Reference!$A$19, Reference!$C$19, IF(J9=Reference!$A$18, Reference!$C$18, IF(J9=Reference!$A$17, Reference!$C$17, 0)))) -> 4 | AA9: =IF(L9=Reference!$A$28, Reference!$C$28, IF(L9=Reference!$A$27, Reference!$C$27, IF(L9=Reference!$A$26, Reference!$C$26, IF(L9=Reference!$A$25, Reference!$C$25, 0)))) -> 7 | AB9: =IF(N9=Reference!$A$36, Reference!$C$36, IF(N9=Reference!$A$35, Reference!$C$35, IF(N9=Reference!$A$34, Reference!$C$34, IF(N9=Reference!$A$33, Reference!$C$33, 0)))) -> 1 | AC9: =(Reference!$B$2*Y9 + Reference!$B$3*AA9 + Reference!$B$4*Z9 + Reference!$B$5*AB9)/4 -> 11.0625 | AD9: =IF(Q9=Reference!$C$41, Reference!$D$41, IF(Q9=Reference!$C$42, Reference!$D$42, IF(Q9=Reference!$C$43, Reference!$D$43, IF(Q9=Reference!$C$44, Reference!$D$44, 0)))) -> 4 | AE9: =1+(AC9*AD9) -> 45.25
A10: T-09 - Sensor communications and configuration | B10: Tampering | C10: Integrity, Authenticity | D10: Manipulation of sensor buses can inject, alter, or reorder multiple sensor messages and compromise several measurements at once. | E10: All sensors → physical buses/interfaces → IUC | F10: Physical | G10: The PDF explicitly identifies physical access as enabling modification, injection, or alteration of sensor messages. | H10: Major | I10: Simultaneous compromise of multiple sensor channels can lead to unsafe environmental decisions. | J10: Moderate | K10: Multi-channel corruption can disrupt monitoring, diagnosis, and maintenance activities. | L10: Major | M10: The source identifies the IUC sensor-ingestion function as an asset where multiple channels can be compromised simultaneously. | N10: Negligible | O10: No direct privacy effect is identified for bus-level tampering. | P10: =IF(AC10>=Reference!$H$2, Reference!$G$2, IF(AC10>=Reference!$H$3, Reference!$G$3, IF(AC10>=Reference!$H$4, Reference!$G$4, IF(AC10>=Reference!$H$5, Reference!$G$5, "")))) -> Severe | Q10: =IF(F10="Physical", "Very Low", IF(F10="Local", "Low", IF(F10="Adjacent", "Medium", IF(F10="Network", "High", "")))) -> Very Low | R10: =IF(AE10>=Reference!$D$2, Reference!$G$2, IF(AE10>=Reference!$D$3, Reference!$E$3, IF(AE10>=Reference!$D$4, Reference!$E$4, IF(AE10>=Reference!$D$5, Reference!$E$5, "")))) -> Low | S10: Risk Reduction | T10: Bus integrity/authentication, physical tamper resistance, message validation, secure diagnostics, anomaly detection | U10: All sensor buses; sensor interfaces; IUC sensor-ingestion function; alarm logic | V10: Protect the shared ingestion boundary because compromise there can affect multiple sensors simultaneously. | W10: Protect sensor communications and configuration from unauthorized modification or injection. | Y10: =IF(H10=Reference!$A$12, Reference!$C$12, IF(H10=Reference!$A$11, Reference!$C$11, IF(H10=Reference!$A$10, Reference!$C$10, IF(H10=Reference!$A$9, Reference!$C$9, 0)))) -> 7 | Z10: =IF(J10=Reference!$A$20, Reference!$C$20, IF(J10=Reference!$A$19, Reference!$C$19, IF(J10=Reference!$A$18, Reference!$C$18, IF(J10=Reference!$A$17, Reference!$C$17, 0)))) -> 4 | AA10: =IF(L10=Reference!$A$28, Reference!$C$28, IF(L10=Reference!$A$27, Reference!$C$27, IF(L10=Reference!$A$26, Reference!$C$26, IF(L10=Reference!$A$25, Reference!$C$25, 0)))) -> 7 | AB10: =IF(N10=Reference!$A$36, Reference!$C$36, IF(N10=Reference!$A$35, Reference!$C$35, IF(N10=Reference!$A$34, Reference!$C$34, IF(N10=Reference!$A$33, Reference!$C$33, 0)))) -> 1 | AC10: =(Reference!$B$2*Y10 + Reference!$B$3*AA10 + Reference!$B$4*Z10 + Reference!$B$5*AB10)/4 -> 11.0625 | AD10: =IF(Q10=Reference!$C$41, Reference!$D$41, IF(Q10=Reference!$C$42, Reference!$D$42, IF(Q10=Reference!$C$43, Reference!$D$43, IF(Q10=Reference!$C$44, Reference!$D$44, 0)))) -> 1 | AE10: =1+(AC10*AD10) -> 12.0625
A11: T-10 - Sensor availability | B11: Denial of Service | C11: Availability | D11: Blocking sensor communications prevents the IUC from receiving environmental measurements and can remove hazard visibility. | E11: All sensor interfaces → IUC | F11: Local | G11: A physical or logical attack prevents one or more sensors from delivering measurements to the IUC. | H11: Major | I11: Loss of all sensor input can contribute to undetected hazardous conditions and missed decisions. | J11: Negligible | K11: The direct financial consequence is not specified in the source, although downtime may cause service costs. | L11: Major | M11: The central monitoring function is materially impaired when measurements are unavailable. | N11: Negligible | O11: No direct privacy impact is identified. | P11: =IF(AC11>=Reference!$H$2, Reference!$G$2, IF(AC11>=Reference!$H$3, Reference!$G$3, IF(AC11>=Reference!$H$4, Reference!$G$4, IF(AC11>=Reference!$H$5, Reference!$G$5, "")))) -> Severe | Q11: =IF(F11="Physical", "Very Low", IF(F11="Local", "Low", IF(F11="Adjacent", "Medium", IF(F11="Network", "High", "")))) -> Low | R11: =IF(AE11>=Reference!$D$2, Reference!$G$2, IF(AE11>=Reference!$D$3, Reference!$E$3, IF(AE11>=Reference!$D$4, Reference!$E$4, IF(AE11>=Reference!$D$5, Reference!$E$5, "")))) -> Medium | S11: Risk Reduction | T11: Interface watchdogs, redundancy, health monitoring, rate limiting, fault detection, fail-safe alerting | U11: Sensor buses/interfaces; IUC ingestion; monitoring and alarm functions | V11: Detect loss of sensor availability and avoid silently treating missing data as safe data. | W11: Maintain availability of sensor measurements and explicitly signal unavailable/untrusted data. | Y11: =IF(H11=Reference!$A$12, Reference!$C$12, IF(H11=Reference!$A$11, Reference!$C$11, IF(H11=Reference!$A$10, Reference!$C$10, IF(H11=Reference!$A$9, Reference!$C$9, 0)))) -> 7 | Z11: =IF(J11=Reference!$A$20, Reference!$C$20, IF(J11=Reference!$A$19, Reference!$C$19, IF(J11=Reference!$A$18, Reference!$C$18, IF(J11=Reference!$A$17, Reference!$C$17, 0)))) -> 1 | AA11: =IF(L11=Reference!$A$28, Reference!$C$28, IF(L11=Reference!$A$27, Reference!$C$27, IF(L11=Reference!$A$26, Reference!$C$26, IF(L11=Reference!$A$25, Reference!$C$25, 0)))) -> 7 | AB11: =IF(N11=Reference!$A$36, Reference!$C$36, IF(N11=Reference!$A$35, Reference!$C$35, IF(N11=Reference!$A$34, Reference!$C$34, IF(N11=Reference!$A$33, Reference!$C$33, 0)))) -> 1 | AC11: =(Reference!$B$2*Y11 + Reference!$B$3*AA11 + Reference!$B$4*Z11 + Reference!$B$5*AB11)/4 -> 10.6875 | AD11: =IF(Q11=Reference!$C$41, Reference!$D$41, IF(Q11=Reference!$C$42, Reference!$D$42, IF(Q11=Reference!$C$43, Reference!$D$43, IF(Q11=Reference!$C$44, Reference!$D$44, 0)))) -> 4 | AE11: =1+(AC11*AD11) -> 43.75
A12: T-11 - Sensor calibration/configuration | B12: Tampering | C12: Integrity, Authenticity | D12: Malicious calibration or scaling changes can create systematic measurement errors that persist across monitoring cycles. | E12: Sensor configuration/calibration → IUC | F12: Physical | G12: Sensor calibration parameters and scaling information are maliciously changed, causing biased measurements. | H12: Major | I12: Systematic errors can suppress hazard detection or produce incorrect environmental assessments. | J12: Moderate | K12: Incorrect calibration can lead to maintenance, re-certification, remediation, and service costs. | L12: Major | M12: Persistent calibration errors degrade the monitoring function across repeated measurements. | N12: Negligible | O12: No direct privacy effect is identified. | P12: =IF(AC12>=Reference!$H$2, Reference!$G$2, IF(AC12>=Reference!$H$3, Reference!$G$3, IF(AC12>=Reference!$H$4, Reference!$G$4, IF(AC12>=Reference!$H$5, Reference!$G$5, "")))) -> Severe | Q12: =IF(F12="Physical", "Very Low", IF(F12="Local", "Low", IF(F12="Adjacent", "Medium", IF(F12="Network", "High", "")))) -> Very Low | R12: =IF(AE12>=Reference!$D$2, Reference!$G$2, IF(AE12>=Reference!$D$3, Reference!$E$3, IF(AE12>=Reference!$D$4, Reference!$E$4, IF(AE12>=Reference!$D$5, Reference!$E$5, "")))) -> Low | S12: Risk Reduction | T12: Signed calibration profiles, authenticated configuration, secure parameter storage, authorization, change audit | U12: Sensor configuration/calibration; sensor controller; IUC ingestion; alarm logic | V12: Secure configuration is required because a correct sensor value is ineffective if its conversion parameters are compromised. | W12: Ensure only authorized, integrity-protected calibration/configuration values are applied. | Y12: =IF(H12=Reference!$A$12, Reference!$C$12, IF(H12=Reference!$A$11, Reference!$C$11, IF(H12=Reference!$A$10, Reference!$C$10, IF(H12=Reference!$A$9, Reference!$C$9, 0)))) -> 7 | Z12: =IF(J12=Reference!$A$20, Reference!$C$20, IF(J12=Reference!$A$19, Reference!$C$19, IF(J12=Reference!$A$18, Reference!$C$18, IF(J12=Reference!$A$17, Reference!$C$17, 0)))) -> 4 | AA12: =IF(L12=Reference!$A$28, Reference!$C$28, IF(L12=Reference!$A$27, Reference!$C$27, IF(L12=Reference!$A$26, Reference!$C$26, IF(L12=Reference!$A$25, Reference!$C$25, 0)))) -> 7 | AB12: =IF(N12=Reference!$A$36, Reference!$C$36, IF(N12=Reference!$A$35, Reference!$C$35, IF(N12=Reference!$A$34, Reference!$C$34, IF(N12=Reference!$A$33, Reference!$C$33, 0)))) -> 1 | AC12: =(Reference!$B$2*Y12 + Reference!$B$3*AA12 + Reference!$B$4*Z12 + Reference!$B$5*AB12)/4 -> 11.0625 | AD12: =IF(Q12=Reference!$C$41, Reference!$D$41, IF(Q12=Reference!$C$42, Reference!$D$42, IF(Q12=Reference!$C$43, Reference!$D$43, IF(Q12=Reference!$C$44, Reference!$D$44, 0)))) -> 1 | AE12: =1+(AC12*AD12) -> 12.0625
A13: T-12 - GPS position/time information | B13: Spoofing | C13: Integrity, Authenticity | D13: Counterfeit GPS/GNSS signals can create incorrect position or time information and misassociate environmental incidents. | E13: GPS RF → GPS receiver → IUC → telemetry/cloud | F13: Adjacent | G13: A nearby RF attacker supplies counterfeit GNSS/GPS signals that influence the position or time reference. | H13: Negligible | I13: The source associates GPS spoofing mainly with location/time correlation rather than direct physical harm. | J13: Negligible | K13: The main operational effect is incorrect incident correlation rather than loss of the monitoring function. | L13: Moderate | M13: Incorrect location/time records can impair incident traceability and context. | N13: Major | O13: GPS/location information is explicitly identified by the source as a privacy-relevant asset when exposed or misassociated. | P13: =IF(AC13>=Reference!$H$2, Reference!$G$2, IF(AC13>=Reference!$H$3, Reference!$G$3, IF(AC13>=Reference!$H$4, Reference!$G$4, IF(AC13>=Reference!$H$5, Reference!$G$5, "")))) -> Moderate | Q13: =IF(F13="Physical", "Very Low", IF(F13="Local", "Low", IF(F13="Adjacent", "Medium", IF(F13="Network", "High", "")))) -> Medium | R13: =IF(AE13>=Reference!$D$2, Reference!$G$2, IF(AE13>=Reference!$D$3, Reference!$E$3, IF(AE13>=Reference!$D$4, Reference!$E$4, IF(AE13>=Reference!$D$5, Reference!$E$5, "")))) -> Medium | S13: Risk Reduction | T13: GNSS anti-spoofing/detection, authenticated time sources, plausibility checks, multi-source location/time validation | U13: GPS receiver; RF interface; IUC; incident timestamp/location data | V13: Use independent time/location plausibility checks because GNSS signals alone are not sufficient evidence of authenticity. | W13: Protect the authenticity and integrity of position/time used for environmental-event correlation. | Y13: =IF(H13=Reference!$A$12, Reference!$C$12, IF(H13=Reference!$A$11, Reference!$C$11, IF(H13=Reference!$A$10, Reference!$C$10, IF(H13=Reference!$A$9, Reference!$C$9, 0)))) -> 1 | Z13: =IF(J13=Reference!$A$20, Reference!$C$20, IF(J13=Reference!$A$19, Reference!$C$19, IF(J13=Reference!$A$18, Reference!$C$18, IF(J13=Reference!$A$17, Reference!$C$17, 0)))) -> 1 | AA13: =IF(L13=Reference!$A$28, Reference!$C$28, IF(L13=Reference!$A$27, Reference!$C$27, IF(L13=Reference!$A$26, Reference!$C$26, IF(L13=Reference!$A$25, Reference!$C$25, 0)))) -> 4 | AB13: =IF(N13=Reference!$A$36, Reference!$C$36, IF(N13=Reference!$A$35, Reference!$C$35, IF(N13=Reference!$A$34, Reference!$C$34, IF(N13=Reference!$A$33, Reference!$C$33, 0)))) -> 7 | AC13: =(Reference!$B$2*Y13 + Reference!$B$3*AA13 + Reference!$B$4*Z13 + Reference!$B$5*AB13)/4 -> 2.8125 | AD13: =IF(Q13=Reference!$C$41, Reference!$D$41, IF(Q13=Reference!$C$42, Reference!$D$42, IF(Q13=Reference!$C$43, Reference!$D$43, IF(Q13=Reference!$C$44, Reference!$D$44, 0)))) -> 7 | AE13: =1+(AC13*AD13) -> 20.6875
... A51: T-50 - End-to-end measurement integrity/authenticity | B51: Tampering | C51: Integrity, Authenticity | D51: A measurement can be selectively modified somewhere between sensor and user while valid-looking transport remains intact, causing the cloud and user to trust false data. | E51: Sensor → IUC → edge → cloud → user | F51: Network | G51: The attacker selectively changes a measurement while preserving apparently valid transport so manipulated data is accepted downstream. | H51: Major | I51: The source identifies end-to-end manipulation as capable of causing system-wide false or suppressed alarms and unsafe decisions. | J51: Major | K51: Persistent false telemetry can corrupt cloud history and require broad investigation and recovery. | L51: Major | M51: The end-to-end monitoring chain can be trusted incorrectly even though each individual link appears available. | N51: Negligible | O51: The principal damage is integrity/authenticity; no direct privacy effect is identified. | P51: =IF(AC51>=Reference!$H$2, Reference!$G$2, IF(AC51>=Reference!$H$3, Reference!$G$3, IF(AC51>=Reference!$H$4, Reference!$G$4, IF(AC51>=Reference!$H$5, Reference!$G$5, "")))) -> Severe | Q51: =IF(F51="Physical", "Very Low", IF(F51="Local", "Low", IF(F51="Adjacent", "Medium", IF(F51="Network", "High", "")))) -> High | R51: =IF(AE51>=Reference!$D$2, Reference!$G$2, IF(AE51>=Reference!$D$3, Reference!$E$3, IF(AE51>=Reference!$D$4, Reference!$E$4, IF(AE51>=Reference!$D$5, Reference!$E$5, "")))) -> Severe | S51: Risk Reduction | T51: End-to-end signatures/MACs, freshness/sequence protection, source binding, path-independent validation, anomaly detection | U51: Sensors; IUC; Far Edge/LoRa Edge; cloud ingestion; dashboard/Status Display | V51: The source stresses that integrity/authenticity must follow the physical measurement all the way to the alarm consumer. | W51: Preserve end-to-end measurement integrity, authenticity and freshness from sensor to user/alarm consumer. | Y51: =IF(H51=Reference!$A$12, Reference!$C$12, IF(H51=Reference!$A$11, Reference!$C$11, IF(H51=Reference!$A$10, Reference!$C$10, IF(H51=Reference!$A$9, Reference!$C$9, 0)))) -> 7 | Z51: =IF(J51=Reference!$A$20, Reference!$C$20, IF(J51=Reference!$A$19, Reference!$C$19, IF(J51=Reference!$A$18, Reference!$C$18, IF(J51=Reference!$A$17, Reference!$C$17, 0)))) -> 7 | AA51: =IF(L51=Reference!$A$28, Reference!$C$28, IF(L51=Reference!$A$27, Reference!$C$27, IF(L51=Reference!$A$26, Reference!$C$26, IF(L51=Reference!$A$25, Reference!$C$25, 0)))) -> 7 | AB51: =IF(N51=Reference!$A$36, Reference!$C$36, IF(N51=Reference!$A$35, Reference!$C$35, IF(N51=Reference!$A$34, Reference!$C$34, IF(N51=Reference!$A$33, Reference!$C$33, 0)))) -> 1 | AC51: =(Reference!$B$2*Y51 + Reference!$B$3*AA51 + Reference!$B$4*Z51 + Reference!$B$5*AB51)/4 -> 11.4375 | AD51: =IF(Q51=Reference!$C$41, Reference!$D$41, IF(Q51=Reference!$C$42, Reference!$D$42, IF(Q51=Reference!$C$43, Reference!$D$43, IF(Q51=Reference!$C$44, Reference!$D$44, 0)))) -> 10 | AE51: =1+(AC51*AD51) -> 115.375

Sheet Reference
A1: Impact Criteria | B1: Weight | D1: Lower Limit | E1: Risk Level | G1: Impact Rating | H1: Threshold Value
A2: Safety | B2: 5 | D2: 100 | E2: Critical | G2: Severe | H2: 8.3
A3: Operational | B3: 1 | D3: 49 | E3: High | G3: Major | H3: 5.1
A4: Financial | B4: 0.5 | D4: 16 | E4: Medium | G4: Moderate | H4: 2.5
A5: Privacy | B5: 0.25 | D5: 1 | E5: Low | G5: Negligible | H5: 1
D6: 0 | E6: Very Low
A7: Safety =>S
A8: Impact Rating | B8: Criteria for Safety Impact Rating | C8: Value
A9: Severe | B9: S3: Life-threatening injuries (survival uncertain), fatal injuries | C9: 10 | G9: Risk Assessment
A10: Major | B10: S2: Severe and life-threatening injuries (survival probable) | C10: 7 | E10: Impact Rating: | G10: Low | H10: Low | I10: Low | J10: Medium | K10: Negligible | L10: Impact Level=>l
A11: Moderate | B11: S1: Light and moderate injuries | C11: 4 | E11: (5*S + 1*O + 0.5*F + 0.25*P) / 4 | G11: Low | H11: Medium | I11: Medium | J11: Medium | K11: Moderate
A12: Negligible | B12: S0: No injuries | C12: 1 | E12: Risk Score: | G12: Low | H12: Medium | I12: High | J12: High | K12: Major
E13: R = 1 + I×F | G13: Medium | H13: High | I13: High | J13: Critical | K13: Severe
G14: Very Low | H14: Low | I14: Medium | J14: High
A15: Reputational => R | G15: Attack Feasibility Level => F
A16: Impact Rating | B16: Criteria for Reputational Impact Rating | C16: Value | E16: Threat category (STRIDE)
A17: Severe | B17: The reputational damage leads to catastrophic consequences which the affected road user might not overcome. | C17: 10 | E17: Spoofing | G17: Risk Score =>R | H17: R = 1 + I × F
A18: Major | B18: The reputational damage leads to substantial consequences which the affected road user will be able to overcome | C18: 7 | E18: Tampering | G18: Risk Appetite | H18: Low
A19: Moderate | B19: The reputational damage leads to inconvenient consequences which the affected road user will be able to overcome with limited resources | C19: 4 | E19: Repudiation | G19: RA Goal: | H19: Risk Reduction
A20: Negligible | B20: The reputational damage leads to no effect, negligible consequences or is irrelevant to the road user. | C20: 1 | E20: Information Disclosure
E21: Denial of Service
E22: Elevation of Privileges
A23: Operational => O
A24: Impact Rating | B24: Criteria for Operational Impact Rating | C24: Value
A25: Severe | B25: The operational damage leads to the loss or impairment of a core vehicle function. EXAMPLE 1 Vehicle not working or showing unexpected behaviour of core functions such as enabling of limp home mode or autonomous driving to an unintended location. | C25: 10
A26: Major | B26: The operational damage leads to the loss or impairment of an important vehicle function. EXAMPLE 2 Significant annoyance of the driver. | C26: 7
A27: Moderate | B27: The operational damage leads to partial degradation of a vehicle function. EXAMPLE 3 User satisfaction negatively affected. | C27: 4
A28: Negligible | B28: The operational damage leads to no impairment or non-perceivable impairment of a vehicle function. | C28: 1
A31: Privacy => P
A32: Impact Rating | B32: Criteria for Privacy Impact Rating | C32: Value
A33: Severe | B33: The privacy damage leads to significant or even irreversible impact to the road user. The information regarding the road user is highly sensitive and easy to link to a PII principal. | C33: 10
A34: Major | B34: The privacy damage leads to serious impact to the road user. The information regarding the road user is: a) highly sensitive and difficult to link to a PII principal; or b) sensitive and easy to link to a PII principal. | C34: 7
A35: Moderate | B35: The privacy damage leads to inconvenient consequences to the road user. The information regarding the road user is: a) sensitive but difficult to link to a PII principal; or b) not sensitive but easy to link to a PII principal. | C35: 4
A36: Negligible | B36: The privacy damage leads to no effect or, negligible consequences or is irrelevant to the road user. The information regarding the road user is not sensitive and difficult to link to a PII principal. | C36: 1
A39: Attack Feasibility Rating => F
A40: Attack Vector | B40: Description | C40: Level | D40: Value
A41: Network | B41: Potential attack path is bound to network stack without any limitation | C41: High | D41: 10
A42: Adjacent | B42: Potential attack path is bound to network stack; however, the connection is limited physically or logically. | C42: Medium | D42: 7
A43: Local | B43: Potential attack path is not bound to network stack and threat agents require direct access to the item for realizing the attack path. | C43: Low | D43: 4
A44: Physical | B44: Threat agents require physical access to realize the attack path. | C44: Very low | D44: 1
...

Sheet Figure Paper 1
