Workbook

Sheet Paper_1
A1: Asset | B1: Threat type | C1: Security Attribute | D1: Damage Scenario | E1: Attack Path | F1: Attack vector | G1: Attack Vector Note / Motiv | H1: Safety Impact | I1: Safety Note / Motiv | J1: Financial Impact | K1: Financial Note / Motiv | L1: Operational Impact | M1: Operational Note / Motiv | N1: Privacy and Legislative Impact | O1: Privacy Note / Motiv | P1: Severity Level | Q1: Feasibility Level | R1: Risk Value | S1: Treatment Options | T1: Measures | U1: Affected Design Elements | V1: Justification (Treatment) | W1: Cybersecurity Goals | Y1: s | Z1: f | AA1: o | AB1: p | AC1: impact | AD1: feasibility val | AE1: Risk score
A2: DENM Management Container- StationType | B2: Tampering | C2: Integrity | D2: The sender changes the StationType between two consecutive DENMs. | E2: The attacker needs access to a legitimate or compromised OBU (On-Board Unit) in the vehicle. | F2: Network | G2: This attack involves manipulating the message content (StationType) within the communication network. | H2: Negligible | I2: No immediate safety impact, but misclassification may affect priority-based decision-making. | J2: Moderate | K2: The impact is minimal and does not lead to substantial losses or any financial threat to the organization. | L2: Moderate | M2: It could cause minor disruption or annoyance if the wrong vehicle type is displayed, but it does not affect core functions. | N2: Negligible | O2: Changing the StationType in a DENM does not involve any privacy-sensitive data (e.g., driver or vehicle-specific information) nor does it directly violate legislation. | P2: =IF(AC2>=Reference!$H$2, Reference!$G$2, IF(AC2>=Reference!$H$3, Reference!$G$3, IF(AC2>=Reference!$H$4, Reference!$G$4, IF(AC2>=Reference!$H$5, Reference!$G$5, "")))) -> Moderate | Q2: =IF(F2="Physical", "Very Low", IF(F2="Local", "Low", IF(F2="Adjacent", "Medium", IF(F2="Network", "High", "")))) -> High | R2: =IF(AE2>=Reference!$D$2, Reference!$G$2, IF(AE2>=Reference!$D$3, Reference!$E$3, IF(AE2>=Reference!$D$4, Reference!$E$4, IF(AE2>=Reference!$D$5, Reference!$E$5, "")))) -> Medium | S2: Mitigation | T2: CAM message verification, Digital Signatures, Anomaly Detection, Rate Limiting, Trust-Based Filtering | U2: Authentication (PKI, Certificates), Message Parsing, Trust Management, CAM Validation, Security Policies, Autonomous Decision-Making | V2: Low impact but needs cryptographic checks and cross-verification with CAM messages. | Y2: =IF(H2=Reference!$A$12, Reference!$C$12, IF(H2=Reference!$A$11, Reference!$C$11, IF(H2=Reference!$A$10, Reference!$C$10, IF(H2=Reference!$A$9, Reference!$C$9, 0)))) -> 1 | Z2: =IF(J2=Reference!$A$20, Reference!$C$20, IF(J2=Reference!$A$19, Reference!$C$19, IF(J2=Reference!$A$18, Reference!$C$18, IF(J2=Reference!$A$17, Reference!$C$17, 0)))) -> 4 | AA2: =IF(L2=Reference!$A$28, Reference!$C$28, IF(L2=Reference!$A$27, Reference!$C$27, IF(L2=Reference!$A$26, Reference!$C$26, IF(L2=Reference!$A$25, Reference!$C$25, 0)))) -> 4 | AB2: =IF(N2=Reference!$A$36, Reference!$C$36, IF(N2=Reference!$A$35, Reference!$C$35, IF(N2=Reference!$A$34, Reference!$C$34, IF(N2=Reference!$A$33, Reference!$C$33, 0)))) -> 1 | AC2: =(Reference!$B$2*Y2 + Reference!$B$3*AA2 + Reference!$B$4*Z2 + Reference!$B$5 * AB2)/4 -> 2.8125 | AD2: =IF(Q2=Reference!$C$41, Reference!$D$41, IF(Q2=Reference!$C$42, Reference!$D$42, IF(Q2=Reference!$C$43, Reference!$D$43, IF(Q2=Reference!$C$44, Reference!$D$44, 0)))) -> 10 | AE2: =1 + (AC2 * AD2) -> 29.125
A3: CO/NO2/SO2/O3 electrochemical sensors -> IUC analog acquisition board (I2C ADC) | B3: Tampering | C3: Integrity | D3: Suppressed CO alert on the Status Display despite dangerous in-cabin concentration -> occupant health harm; no driver warning to ventilate or stop. Safety. | E3: Attacker with brief physical access injects a DC bias or clamps the analog mV output line from the electrochemical sensor (e.g. via the exposed 3.5 mm debug/service connector), forcing artificially low readings before ADC digitization. | F3: Physical | G3: Requires the attacker to physically reach the exposed debug/service connector on the sensor unit; no network path is involved. | H3: Severe | I3: Undetected CO buildup can cause loss of consciousness or death if occupants receive no warning to ventilate. | J3: Moderate | K3: Limited direct financial loss, but potential liability exposure if the failure to warn contributes to injury. | L3: Major | M3: The core air-quality alerting function is disabled for the affected sensor channel. | N3: Negligible | O3: No personal or location data is affected by this tampering. | P3: =IF(AC3>=Reference!$H$2, Reference!$G$2, IF(AC3>=Reference!$H$3, Reference!$G$3, IF(AC3>=Reference!$H$4, Reference!$G$4, IF(AC3>=Reference!$H$5, Reference!$G$5, "")))) -> Severe | Q3: =IF(F3="Physical", "Very Low", IF(F3="Local", "Low", IF(F3="Adjacent", "Medium", IF(F3="Network", "High", "")))) -> Very Low | R3: =IF(AE3>=Reference!$D$2, Reference!$G$2, IF(AE3>=Reference!$D$3, Reference!$E$3, IF(AE3>=Reference!$D$4, Reference!$E$4, IF(AE3>=Reference!$D$5, Reference!$E$5, "")))) -> Low | S3: Mitigation | T3: Tamper-evident enclosure for the debug/service connector; signed/authenticated sensor firmware; plausibility/range checks on raw ADC readings; redundant CO sensing or cross-checking against other channels. | U3: Electrochemical sensor analog front-end, I2C ADC, sensor-unit enclosure/debug connector. | V3: High safety severity combined with low attack feasibility (physical access needed) still yields a risk that must be reduced via tamper protection and input validation. | W3: Ensure integrity of raw gas-concentration readings from sensor to ADC. | Y3: =IF(H3=Reference!$A$12, Reference!$C$12, IF(H3=Reference!$A$11, Reference!$C$11, IF(H3=Reference!$A$10, Reference!$C$10, IF(H3=Reference!$A$9, Reference!$C$9, 0)))) -> 10 | Z3: =IF(J3=Reference!$A$20, Reference!$C$20, IF(J3=Reference!$A$19, Reference!$C$19, IF(J3=Reference!$A$18, Reference!$C$18, IF(J3=Reference!$A$17, Reference!$C$17, 0)))) -> 4 | AA3: =IF(L3=Reference!$A$28, Reference!$C$28, IF(L3=Reference!$A$27, Reference!$C$27, IF(L3=Reference!$A$26, Reference!$C$26, IF(L3=Reference!$A$25, Reference!$C$25, 0)))) -> 7 | AB3: =IF(N3=Reference!$A$36, Reference!$C$36, IF(N3=Reference!$A$35, Reference!$C$35, IF(N3=Reference!$A$34, Reference!$C$34, IF(N3=Reference!$A$33, Reference!$C$33, 0)))) -> 1 | AC3: =(Reference!$B$2*Y3 + Reference!$B$3*AA3 + Reference!$B$4*Z3 + Reference!$B$5 * AB3)/4 -> 14.8125 | AD3: =IF(Q3=Reference!$C$41, Reference!$D$41, IF(Q3=Reference!$C$42, Reference!$D$42, IF(Q3=Reference!$C$43, Reference!$D$43, IF(Q3=Reference!$C$44, Reference!$D$44, 0)))) -> 1 | AE3: =1 + (AC3 * AD3) -> 15.8125
A4: Shared I2C bus (PM2.5/PM10, gas ADC, GNSS-adjacent bus) | B4: Tampering | C4: Integrity | D4: Cascading loss of PM/gas telemetry; IUC freezes last-known-good values or reports garbage, uploading a false 'safe' status. Safety / Operational. | E4: A rogue device or induced fault on the shared I2C bus (bus contention, address spoofing, clock-stretching abuse) corrupts or blocks several sensor readings simultaneously. | F4: Physical | G4: Compromising the shared I2C bus requires direct physical/electrical access to the sensor unit's internal wiring. | H4: Major | I4: A false 'safe' status masking a genuine multi-channel pollution event could lead to severe occupant harm. | J4: Moderate | K4: Possible liability from false 'safe' readings shown to users; moderate reputational cost. | L4: Severe | M4: Simultaneous corruption of several sensor channels degrades a core monitoring function. | N4: Negligible | O4: No PII involved. | P4: =IF(AC4>=Reference!$H$2, Reference!$G$2, IF(AC4>=Reference!$H$3, Reference!$G$3, IF(AC4>=Reference!$H$4, Reference!$G$4, IF(AC4>=Reference!$H$5, Reference!$G$5, "")))) -> Severe | Q4: =IF(F4="Physical", "Very Low", IF(F4="Local", "Low", IF(F4="Adjacent", "Medium", IF(F4="Network", "High", "")))) -> Very Low | R4: =IF(AE4>=Reference!$D$2, Reference!$G$2, IF(AE4>=Reference!$D$3, Reference!$E$3, IF(AE4>=Reference!$D$4, Reference!$E$4, IF(AE4>=Reference!$D$5, Reference!$E$5, "")))) -> Low | S4: Mitigation | T4: Bus-level authentication or address whitelisting, watchdog/plausibility checks across channels, physical shielding of the I2C bus, isolation of the GNSS-adjacent bus segment. | U4: I2C bus, PM2.5/PM10 sensor, gas ADC, sensor-unit housing. | V4: Multi-channel cascading failure combined with false-safe reporting drives high operational/safety risk; feasibility is low due to the need for physical bus access, but consequence severity justifies mitigation. | W4: Ensure integrity and availability of all sensor channels sharing the I2C bus. | Y4: =IF(H4=Reference!$A$12, Reference!$C$12, IF(H4=Reference!$A$11, Reference!$C$11, IF(H4=Reference!$A$10, Reference!$C$10, IF(H4=Reference!$A$9, Reference!$C$9, 0)))) -> 7 | Z4: =IF(J4=Reference!$A$20, Reference!$C$20, IF(J4=Reference!$A$19, Reference!$C$19, IF(J4=Reference!$A$18, Reference!$C$18, IF(J4=Reference!$A$17, Reference!$C$17, 0)))) -> 4 | AA4: =IF(L4=Reference!$A$28, Reference!$C$28, IF(L4=Reference!$A$27, Reference!$C$27, IF(L4=Reference!$A$26, Reference!$C$26, IF(L4=Reference!$A$25, Reference!$C$25, 0)))) -> 10 | AB4: =IF(N4=Reference!$A$36, Reference!$C$36, IF(N4=Reference!$A$35, Reference!$C$35, IF(N4=Reference!$A$34, Reference!$C$34, IF(N4=Reference!$A$33, Reference!$C$33, 0)))) -> 1 | AC4: =(Reference!$B$2*Y4 + Reference!$B$3*AA4 + Reference!$B$4*Z4 + Reference!$B$5 * AB4)/4 -> 11.8125 | AD4: =IF(Q4=Reference!$C$41, Reference!$D$41, IF(Q4=Reference!$C$42, Reference!$D$42, IF(Q4=Reference!$C$43, Reference!$D$43, IF(Q4=Reference!$C$44, Reference!$D$44, 0)))) -> 1 | AE4: =1 + (AC4 * AD4) -> 12.8125
A5: Sensor-unit firmware (MicroPython on ESP32/PyCom FiPy SoC) | B5: Tampering | C5: Integrity | D5: Persistent falsification of all onward telemetry with no physical evidence of tampering, undermining every downstream alert and dataset. Safety / Financial. | E5: Attacker with local access to the unit's debug/firmware-update jack flashes modified firmware that fixes sensor register values or disables the fault-tolerant sampling logic. | F5: Physical | G5: Flashing firmware requires physical access to the debug/firmware-update jack. | H5: Major | I5: All future alerts derived from this node become unreliable, potentially masking real hazards indefinitely. | J5: Major | K5: Undetectable persistent compromise can require costly fleet-wide audits, node replacement, and data invalidation. | L5: Severe | M5: Falsified telemetry corrupts the unit's entire operational function persistently. | N5: Negligible | O5: No PII directly exposed, though downstream location-tagged data integrity is also affected. | P5: =IF(AC5>=Reference!$H$2, Reference!$G$2, IF(AC5>=Reference!$H$3, Reference!$G$3, IF(AC5>=Reference!$H$4, Reference!$G$4, IF(AC5>=Reference!$H$5, Reference!$G$5, "")))) -> Severe | Q5: =IF(F5="Physical", "Very Low", IF(F5="Local", "Low", IF(F5="Adjacent", "Medium", IF(F5="Network", "High", "")))) -> Very Low | R5: =IF(AE5>=Reference!$D$2, Reference!$G$2, IF(AE5>=Reference!$D$3, Reference!$E$3, IF(AE5>=Reference!$D$4, Reference!$E$4, IF(AE5>=Reference!$D$5, Reference!$E$5, "")))) -> Low | S5: Mitigation | T5: Secure boot, signed firmware updates, disable/lock the debug port in production, firmware integrity attestation to the far-edge device. | U5: ESP32/PyCom FiPy SoC firmware, debug/firmware-update interface. | V5: The severity and stealth of persistent falsification outweigh the low feasibility (physical access needed); secure boot is a standard, proportionate control. | W5: Ensure authenticity and integrity of sensor-unit firmware. | Y5: =IF(H5=Reference!$A$12, Reference!$C$12, IF(H5=Reference!$A$11, Reference!$C$11, IF(H5=Reference!$A$10, Reference!$C$10, IF(H5=Reference!$A$9, Reference!$C$9, 0)))) -> 7 | Z5: =IF(J5=Reference!$A$20, Reference!$C$20, IF(J5=Reference!$A$19, Reference!$C$19, IF(J5=Reference!$A$18, Reference!$C$18, IF(J5=Reference!$A$17, Reference!$C$17, 0)))) -> 7 | AA5: =IF(L5=Reference!$A$28, Reference!$C$28, IF(L5=Reference!$A$27, Reference!$C$27, IF(L5=Reference!$A$26, Reference!$C$26, IF(L5=Reference!$A$25, Reference!$C$25, 0)))) -> 10 | AB5: =IF(N5=Reference!$A$36, Reference!$C$36, IF(N5=Reference!$A$35, Reference!$C$35, IF(N5=Reference!$A$34, Reference!$C$34, IF(N5=Reference!$A$33, Reference!$C$33, 0)))) -> 1 | AC5: =(Reference!$B$2*Y5 + Reference!$B$3*AA5 + Reference!$B$4*Z5 + Reference!$B$5 * AB5)/4 -> 12.1875 | AD5: =IF(Q5=Reference!$C$41, Reference!$D$41, IF(Q5=Reference!$C$42, Reference!$D$42, IF(Q5=Reference!$C$43, Reference!$D$43, IF(Q5=Reference!$C$44, Reference!$D$44, 0)))) -> 1 | AE5: =1 + (AC5 * AD5) -> 13.1875
A6: Sensor-unit firmware (MicroPython on ESP32/PyCom FiPy SoC) - debug/firmware-update jack | B6: Elevation of privilege | C6: Integrity | D6: Attacker gains full control of the sensor node itself, enabling any of the above tampering effects plus use of the node as a foothold to attack the WiFi/LoRa links it feeds. Operational / Financial. | E6: The same physically-exposed debug/firmware-update jack grants an attacker privileged code-execution rights beyond the intended firmware-update scope, allowing arbitrary code to run at the level of the device's core sampling/communication logic. | F6: Physical | G6: Exploiting the debug jack's excess privilege requires the same physical access as SEN-03a. | H6: Major | I6: Full node compromise enables every safety-relevant tampering effect described for the same node. | J6: Major | K6: A fully compromised node becomes a durable foothold, increasing incident-response and remediation cost. | L6: Severe | M6: Complete loss of trust in the node's core sampling/communication logic. | N6: Negligible | O6: No direct PII, though the node could be leveraged to pivot toward privacy-relevant links (WiFi/LoRa). | P6: =IF(AC6>=Reference!$H$2, Reference!$G$2, IF(AC6>=Reference!$H$3, Reference!$G$3, IF(AC6>=Reference!$H$4, Reference!$G$4, IF(AC6>=Reference!$H$5, Reference!$G$5, "")))) -> Severe | Q6: =IF(F6="Physical", "Very Low", IF(F6="Local", "Low", IF(F6="Adjacent", "Medium", IF(F6="Network", "High", "")))) -> Very Low | R6: =IF(AE6>=Reference!$D$2, Reference!$G$2, IF(AE6>=Reference!$D$3, Reference!$E$3, IF(AE6>=Reference!$D$4, Reference!$E$4, IF(AE6>=Reference!$D$5, Reference!$E$5, "")))) -> Low | S6: Mitigation | T6: Restrict debug interface privileges to firmware-update only, hardware secure element, disable JTAG/debug in production units, network segmentation for compromised-node containment. | U6: Debug/firmware-update jack, SoC execution environment, sensor-unit firmware. | V6: This is the root-cause enabler for several other threats; hardening the debug interface materially reduces the whole sensor-unit attack surface. | W6: Restrict the debug/firmware-update interface to its intended privilege scope. | Y6: =IF(H6=Reference!$A$12, Reference!$C$12, IF(H6=Reference!$A$11, Reference!$C$11, IF(H6=Reference!$A$10, Reference!$C$10, IF(H6=Reference!$A$9, Reference!$C$9, 0)))) -> 7 | Z6: =IF(J6=Reference!$A$20, Reference!$C$20, IF(J6=Reference!$A$19, Reference!$C$19, IF(J6=Reference!$A$18, Reference!$C$18, IF(J6=Reference!$A$17, Reference!$C$17, 0)))) -> 7 | AA6: =IF(L6=Reference!$A$28, Reference!$C$28, IF(L6=Reference!$A$27, Reference!$C$27, IF(L6=Reference!$A$26, Reference!$C$26, IF(L6=Reference!$A$25, Reference!$C$25, 0)))) -> 10 | AB6: =IF(N6=Reference!$A$36, Reference!$C$36, IF(N6=Reference!$A$35, Reference!$C$35, IF(N6=Reference!$A$34, Reference!$C$34, IF(N6=Reference!$A$33, Reference!$C$33, 0)))) -> 1 | AC6: =(Reference!$B$2*Y6 + Reference!$B$3*AA6 + Reference!$B$4*Z6 + Reference!$B$5 * AB6)/4 -> 12.1875 | AD6: =IF(Q6=Reference!$C$41, Reference!$D$41, IF(Q6=Reference!$C$42, Reference!$D$42, IF(Q6=Reference!$C$43, Reference!$D$43, IF(Q6=Reference!$C$44, Reference!$D$44, 0)))) -> 1 | AE6: =1 + (AC6 * AD6) -> 13.1875
A7: Sensor sampling loop / power subsystem | B7: Denial of service | C7: Availability | D7: IUC reports 'sensor not stabilized'/stale data; occupants receive no real-time warning during an actual pollution event. Safety. | E7: Deliberate power-line noise injection or manipulation of the physically-accessible battery-isolation relay starves gas sensors of clean power, causing stabilization failures. | F7: Physical | G7: The battery-isolation relay and power lines require physical access to manipulate. | H7: Major | I7: No warning is available exactly when a real hazardous exposure occurs. | J7: Moderate | K7: Minor cost from replacement/diagnostics; low direct financial exposure. | L7: Major | M7: Loss of stabilized sensor readings degrades an important monitoring function. | N7: Negligible | O7: No PII involved. | P7: =IF(AC7>=Reference!$H$2, Reference!$G$2, IF(AC7>=Reference!$H$3, Reference!$G$3, IF(AC7>=Reference!$H$4, Reference!$G$4, IF(AC7>=Reference!$H$5, Reference!$G$5, "")))) -> Severe | Q7: =IF(F7="Physical", "Very Low", IF(F7="Local", "Low", IF(F7="Adjacent", "Medium", IF(F7="Network", "High", "")))) -> Very Low | R7: =IF(AE7>=Reference!$D$2, Reference!$G$2, IF(AE7>=Reference!$D$3, Reference!$E$3, IF(AE7>=Reference!$D$4, Reference!$E$4, IF(AE7>=Reference!$D$5, Reference!$E$5, "")))) -> Low | S7: Mitigation | T7: Physical protection/locking of relay and power lines, power-line filtering, brownout detection and alerting, backup power buffering. | U7: Battery-isolation relay, sensor power subsystem. | V7: Low-cost physical hardening (locking/shielding) substantially reduces likelihood while consequence remains safety-relevant. | W7: Ensure availability of clean power to the sensor sampling loop. | Y7: =IF(H7=Reference!$A$12, Reference!$C$12, IF(H7=Reference!$A$11, Reference!$C$11, IF(H7=Reference!$A$10, Reference!$C$10, IF(H7=Reference!$A$9, Reference!$C$9, 0)))) -> 7 | Z7: =IF(J7=Reference!$A$20, Reference!$C$20, IF(J7=Reference!$A$19, Reference!$C$19, IF(J7=Reference!$A$18, Reference!$C$18, IF(J7=Reference!$A$17, Reference!$C$17, 0)))) -> 4 | AA7: =IF(L7=Reference!$A$28, Reference!$C$28, IF(L7=Reference!$A$27, Reference!$C$27, IF(L7=Reference!$A$26, Reference!$C$26, IF(L7=Reference!$A$25, Reference!$C$25, 0)))) -> 7 | AB7: =IF(N7=Reference!$A$36, Reference!$C$36, IF(N7=Reference!$A$35, Reference!$C$35, IF(N7=Reference!$A$34, Reference!$C$34, IF(N7=Reference!$A$33, Reference!$C$33, 0)))) -> 1 | AC7: =(Reference!$B$2*Y7 + Reference!$B$3*AA7 + Reference!$B$4*Z7 + Reference!$B$5 * AB7)/4 -> 11.0625 | AD7: =IF(Q7=Reference!$C$41, Reference!$D$41, IF(Q7=Reference!$C$42, Reference!$D$42, IF(Q7=Reference!$C$43, Reference!$D$43, IF(Q7=Reference!$C$44, Reference!$D$44, 0)))) -> 1 | AE7: =1 + (AC7 * AD7) -> 12.0625
A8: Raw 32-byte sensor data frame (inner unit -> outer unit -> far-edge device) | B8: Repudiation | C8: Integrity | D8: Regulatory/liability disputes over recorded exposure data cannot be resolved -- falsified records are indistinguishable from genuine ones. Financial / Operational. | E8: The compact frame format carries no cryptographic signature or per-frame authentication tag; a compromised node anywhere in the chain can inject or alter frames with no way to later prove which node produced which value. | F8: Local | G8: Exploiting the missing per-frame authentication requires control of a node already on the internal sensor-to-edge path. | H8: Negligible | I8: No direct safety consequence; the impact is evidentiary/legal. | J8: Major | K8: Unresolved liability and regulatory disputes over falsified exposure records carry material financial risk. | L8: Moderate | M8: Undermines confidence in the dataset but does not directly disable a vehicle function. | N8: Negligible | O8: No new PII exposure, though data provenance about a specific vehicle is affected. | P8: =IF(AC8>=Reference!$H$2, Reference!$G$2, IF(AC8>=Reference!$H$3, Reference!$G$3, IF(AC8>=Reference!$H$4, Reference!$G$4, IF(AC8>=Reference!$H$5, Reference!$G$5, "")))) -> Moderate | Q8: =IF(F8="Physical", "Very Low", IF(F8="Local", "Low", IF(F8="Adjacent", "Medium", IF(F8="Network", "High", "")))) -> Low | R8: =IF(AE8>=Reference!$D$2, Reference!$G$2, IF(AE8>=Reference!$D$3, Reference!$E$3, IF(AE8>=Reference!$D$4, Reference!$E$4, IF(AE8>=Reference!$D$5, Reference!$E$5, "")))) -> Low | S8: Mitigation | T8: Per-frame message authentication codes (MAC), cryptographic signing at node level, tamper-evident logging, key provisioning per sensor unit. | U8: 32-byte sensor frame format, inner/outer unit communication link. | V8: The low implementation cost of a MAC is disproportionate to the financial/legal exposure from unresolvable disputes. | W8: Ensure non-repudiation and authenticity of sensor measurement provenance. | Y8: =IF(H8=Reference!$A$12, Reference!$C$12, IF(H8=Reference!$A$11, Reference!$C$11, IF(H8=Reference!$A$10, Reference!$C$10, IF(H8=Reference!$A$9, Reference!$C$9, 0)))) -> 1 | Z8: =IF(J8=Reference!$A$20, Reference!$C$20, IF(J8=Reference!$A$19, Reference!$C$19, IF(J8=Reference!$A$18, Reference!$C$18, IF(J8=Reference!$A$17, Reference!$C$17, 0)))) -> 7 | AA8: =IF(L8=Reference!$A$28, Reference!$C$28, IF(L8=Reference!$A$27, Reference!$C$27, IF(L8=Reference!$A$26, Reference!$C$26, IF(L8=Reference!$A$25, Reference!$C$25, 0)))) -> 4 | AB8: =IF(N8=Reference!$A$36, Reference!$C$36, IF(N8=Reference!$A$35, Reference!$C$35, IF(N8=Reference!$A$34, Reference!$C$34, IF(N8=Reference!$A$33, Reference!$C$33, 0)))) -> 1 | AC8: =(Reference!$B$2*Y8 + Reference!$B$3*AA8 + Reference!$B$4*Z8 + Reference!$B$5 * AB8)/4 -> 3.1875 | AD8: =IF(Q8=Reference!$C$41, Reference!$D$41, IF(Q8=Reference!$C$42, Reference!$D$42, IF(Q8=Reference!$C$43, Reference!$D$43, IF(Q8=Reference!$C$44, Reference!$D$44, 0)))) -> 4 | AE8: =1 + (AC8 * AD8) -> 13.75
A9: In-vehicle WiFi (router access point; sensor units as clients) | B9: Spoofing | C9: Integrity | D9: Sensor telemetry is silently diverted or dropped before reaching the far-edge device and 4G uplink; system appears to operate normally while no data reaches the cloud. Operational / Safety. | E9: Attacker parked nearby stands up a rogue AP cloning the vehicle's SSID/credentials, inducing the sensor units to associate with it instead of the legitimate far-edge device. | F9: Adjacent | G9: The rogue-AP attack is bound to the WiFi network stack but limited to attacker proximity to the vehicle. | H9: Major | I9: Silent telemetry loss removes any chance of a real-time or cloud-side alert during an actual pollution event. | J9: Moderate | K9: Gaps in fleet data reduce dataset value and may require remediation, moderate cost. | L9: Major | M9: The sensor-to-cloud data path is fully defeated while appearing nominal. | N9: Moderate | O9: Traffic redirected through a rogue AP could also be read by the attacker, exposing vehicle telemetry and location. | P9: =IF(AC9>=Reference!$H$2, Reference!$G$2, IF(AC9>=Reference!$H$3, Reference!$G$3, IF(AC9>=Reference!$H$4, Reference!$G$4, IF(AC9>=Reference!$H$5, Reference!$G$5, "")))) -> Severe | Q9: =IF(F9="Physical", "Very Low", IF(F9="Local", "Low", IF(F9="Adjacent", "Medium", IF(F9="Network", "High", "")))) -> Medium | R9: =IF(AE9>=Reference!$D$2, Reference!$G$2, IF(AE9>=Reference!$D$3, Reference!$E$3, IF(AE9>=Reference!$D$4, Reference!$E$4, IF(AE9>=Reference!$D$5, Reference!$E$5, "")))) -> High | S9: Mitigation | T9: Mutual authentication (WPA2/3-Enterprise or certificate-based), AP whitelisting via BSSID/certificate pinning, rogue-AP detection, fallback health-check via LoRa/4G. | U9: In-vehicle WiFi AP/router, sensor-unit WiFi client stack. | V9: Adjacent-range attack feasibility is limited but the complete, silent loss of the primary uplink path justifies strong mutual authentication. | W9: Ensure authenticity of the in-vehicle WiFi access point to sensor-unit clients. | Y9: =IF(H9=Reference!$A$12, Reference!$C$12, IF(H9=Reference!$A$11, Reference!$C$11, IF(H9=Reference!$A$10, Reference!$C$10, IF(H9=Reference!$A$9, Reference!$C$9, 0)))) -> 7 | Z9: =IF(J9=Reference!$A$20, Reference!$C$20, IF(J9=Reference!$A$19, Reference!$C$19, IF(J9=Reference!$A$18, Reference!$C$18, IF(J9=Reference!$A$17, Reference!$C$17, 0)))) -> 4 | AA9: =IF(L9=Reference!$A$28, Reference!$C$28, IF(L9=Reference!$A$27, Reference!$C$27, IF(L9=Reference!$A$26, Reference!$C$26, IF(L9=Reference!$A$25, Reference!$C$25, 0)))) -> 7 | AB9: =IF(N9=Reference!$A$36, Reference!$C$36, IF(N9=Reference!$A$35, Reference!$C$35, IF(N9=Reference!$A$34, Reference!$C$34, IF(N9=Reference!$A$33, Reference!$C$33, 0)))) -> 4 | AC9: =(Reference!$B$2*Y9 + Reference!$B$3*AA9 + Reference!$B$4*Z9 + Reference!$B$5 * AB9)/4 -> 11.25 | AD9: =IF(Q9=Reference!$C$41, Reference!$D$41, IF(Q9=Reference!$C$42, Reference!$D$42, IF(Q9=Reference!$C$43, Reference!$D$43, IF(Q9=Reference!$C$44, Reference!$D$44, 0)))) -> 7 | AE9: =1 + (AC9 * AD9) -> 79.75
A10: In-vehicle WiFi TCP/IP socket (sensor unit -> far-edge decoder pod) | B10: Tampering | C10: Integrity | D10: Falsified in-cabin CO2/CO values reach the real-time in-vehicle alert, masking real danger or triggering nuisance false alarms. Safety / Operational. | E10: Attacker on the same WiFi segment performs a MitM on the plaintext TCP socket carrying raw sensor frames, altering pollutant values before they reach the decoder pod. | F10: Adjacent | G10: MitM requires the attacker to be associated with the same WiFi segment, limited to network-adjacent range. | H10: Severe | I10: Masking a genuine hazardous reading can directly lead to occupant harm from undetected exposure. | J10: Moderate | K10: Nuisance false alarms and post-incident investigation carry moderate cost. | L10: Major | M10: The real-time alerting function is directly compromised. | N10: Negligible | O10: No PII exposed by this tampering alone. | P10: =IF(AC10>=Reference!$H$2, Reference!$G$2, IF(AC10>=Reference!$H$3, Reference!$G$3, IF(AC10>=Reference!$H$4, Reference!$G$4, IF(AC10>=Reference!$H$5, Reference!$G$5, "")))) -> Severe | Q10: =IF(F10="Physical", "Very Low", IF(F10="Local", "Low", IF(F10="Adjacent", "Medium", IF(F10="Network", "High", "")))) -> Medium | R10: =IF(AE10>=Reference!$D$2, Reference!$G$2, IF(AE10>=Reference!$D$3, Reference!$E$3, IF(AE10>=Reference!$D$4, Reference!$E$4, IF(AE10>=Reference!$D$5, Reference!$E$5, "")))) -> Severe | S10: Mitigation | T10: TLS/DTLS on the sensor-to-decoder socket, mutual authentication, integrity MAC on payload, WiFi client isolation at the AP level. | U10: TCP/IP socket, decoder pod ingestion logic. | V10: Plaintext transport for a safety-relevant channel is a high-severity gap that a standard TLS/MAC control directly closes. | W10: Ensure integrity and confidentiality of sensor frames in transit over WiFi. | Y10: =IF(H10=Reference!$A$12, Reference!$C$12, IF(H10=Reference!$A$11, Reference!$C$11, IF(H10=Reference!$A$10, Reference!$C$10, IF(H10=Reference!$A$9, Reference!$C$9, 0)))) -> 10 | Z10: =IF(J10=Reference!$A$20, Reference!$C$20, IF(J10=Reference!$A$19, Reference!$C$19, IF(J10=Reference!$A$18, Reference!$C$18, IF(J10=Reference!$A$17, Reference!$C$17, 0)))) -> 4 | AA10: =IF(L10=Reference!$A$28, Reference!$C$28, IF(L10=Reference!$A$27, Reference!$C$27, IF(L10=Reference!$A$26, Reference!$C$26, IF(L10=Reference!$A$25, Reference!$C$25, 0)))) -> 7 | AB10: =IF(N10=Reference!$A$36, Reference!$C$36, IF(N10=Reference!$A$35, Reference!$C$35, IF(N10=Reference!$A$34, Reference!$C$34, IF(N10=Reference!$A$33, Reference!$C$33, 0)))) -> 1 | AC10: =(Reference!$B$2*Y10 + Reference!$B$3*AA10 + Reference!$B$4*Z10 + Reference!$B$5 * AB10)/4 -> 14.8125 | AD10: =IF(Q10=Reference!$C$41, Reference!$D$41, IF(Q10=Reference!$C$42, Reference!$D$42, IF(Q10=Reference!$C$43, Reference!$D$43, IF(Q10=Reference!$C$44, Reference!$D$44, 0)))) -> 7 | AE10: =1 + (AC10 * AD10) -> 104.6875
A11: 2.4 GHz WiFi RF channel | B11: Denial of service | C11: Availability | D11: Complete loss of in-cabin monitoring and local alert broadcast; only the already-lossy LoRaWAN path remains, removing redundancy exactly where an attacker wants a blind spot. Safety / Operational. | E11: RF jamming or deauthentication flooding of the 2.4 GHz band disconnects sensor units from the far-edge device. | F11: Adjacent | G11: Jamming/deauth requires RF proximity to the vehicle but no physical contact or credentials. | H11: Major | I11: Loss of the primary in-cabin alert path removes real-time protection, relying on a degraded backup. | J11: Moderate | K11: Limited direct financial impact beyond data gaps. | L11: Severe | M11: Removes the primary link and leaves only a known-lossy backup, a core function impairment. | N11: Negligible | O11: No PII exposure from jamming. | P11: =IF(AC11>=Reference!$H$2, Reference!$G$2, IF(AC11>=Reference!$H$3, Reference!$G$3, IF(AC11>=Reference!$H$4, Reference!$G$4, IF(AC11>=Reference!$H$5, Reference!$G$5, "")))) -> Severe | Q11: =IF(F11="Physical", "Very Low", IF(F11="Local", "Low", IF(F11="Adjacent", "Medium", IF(F11="Network", "High", "")))) -> Medium | R11: =IF(AE11>=Reference!$D$2, Reference!$G$2, IF(AE11>=Reference!$D$3, Reference!$E$3, IF(AE11>=Reference!$D$4, Reference!$E$4, IF(AE11>=Reference!$D$5, Reference!$E$5, "")))) -> High | S11: Mitigation | T11: Spread-spectrum/channel-hopping resilience, RF jamming detection with driver alert, dual-path failover with a local non-networked audible alarm as last resort. | U11: 2.4 GHz WiFi radio, far-edge device WiFi interface. | V11: Jamming is cheap and hard to fully prevent; adding a local, non-networked fail-safe alarm meaningfully reduces consequence severity. | W11: Ensure availability of the sensor-to-edge WiFi link, or a fail-safe local alert if lost. | Y11: =IF(H11=Reference!$A$12, Reference!$C$12, IF(H11=Reference!$A$11, Reference!$C$11, IF(H11=Reference!$A$10, Reference!$C$10, IF(H11=Reference!$A$9, Reference!$C$9, 0)))) -> 7 | Z11: =IF(J11=Reference!$A$20, Reference!$C$20, IF(J11=Reference!$A$19, Reference!$C$19, IF(J11=Reference!$A$18, Reference!$C$18, IF(J11=Reference!$A$17, Reference!$C$17, 0)))) -> 4 | AA11: =IF(L11=Reference!$A$28, Reference!$C$28, IF(L11=Reference!$A$27, Reference!$C$27, IF(L11=Reference!$A$26, Reference!$C$26, IF(L11=Reference!$A$25, Reference!$C$25, 0)))) -> 10 | AB11: =IF(N11=Reference!$A$36, Reference!$C$36, IF(N11=Reference!$A$35, Reference!$C$35, IF(N11=Reference!$A$34, Reference!$C$34, IF(N11=Reference!$A$33, Reference!$C$33, 0)))) -> 1 | AC11: =(Reference!$B$2*Y11 + Reference!$B$3*AA11 + Reference!$B$4*Z11 + Reference!$B$5 * AB11)/4 -> 11.8125 | AD11: =IF(Q11=Reference!$C$41, Reference!$D$41, IF(Q11=Reference!$C$42, Reference!$D$42, IF(Q11=Reference!$C$43, Reference!$D$43, IF(Q11=Reference!$C$44, Reference!$D$44, 0)))) -> 7 | AE11: =1 + (AC11 * AD11) -> 83.6875
A12: Far-edge device NodePort services (decoder pod, database) exposed on in-vehicle WiFi | B12: Elevation of privilege | C12: Confidentiality | D12: Full compromise of the far-edge Kubernetes node, enabling data exfiltration, persistent malware implantation, or use of the vehicle as a pivot into the fleet backend. Financial / Operational / Privacy. | E12: Decoder and database pods are exposed via NodePort on the internal WiFi network; an attacker who joins that network can reach unauthenticated or default-credentialed service ports directly. | F12: Adjacent | G12: Reaching the NodePort services requires association to the in-vehicle WiFi network, i.e. adjacent access. | H12: Moderate | I12: Indirect safety risk if the compromised node is later used to falsify or suppress alerts. | J12: Severe | K12: A durable foothold into the fleet backend represents a major financial/liability exposure across the fleet. | L12: Major | M12: Compromise of the decoder/database pods disables reliable local processing and storage. | N12: Major | O12: Locally buffered sensor/diagnostic data is exposed to exfiltration once the node is compromised. | P12: =IF(AC12>=Reference!$H$2, Reference!$G$2, IF(AC12>=Reference!$H$3, Reference!$G$3, IF(AC12>=Reference!$H$4, Reference!$G$4, IF(AC12>=Reference!$H$5, Reference!$G$5, "")))) -> Severe | Q12: =IF(F12="Physical", "Very Low", IF(F12="Local", "Low", IF(F12="Adjacent", "Medium", IF(F12="Network", "High", "")))) -> Medium | R12: =IF(AE12>=Reference!$D$2, Reference!$G$2, IF(AE12>=Reference!$D$3, Reference!$E$3, IF(AE12>=Reference!$D$4, Reference!$E$4, IF(AE12>=Reference!$D$5, Reference!$E$5, "")))) -> High | S12: Mitigation | T12: Remove/restrict NodePort exposure (use ClusterIP plus authenticated ingress), strong unique credentials, network policies/segmentation, k3s RBAC hardening, regular patching. | U12: k3s NodePort services, decoder pod, database pod. | V12: Default/weak credentials on exposed services are a well-known, easily fixed root cause with severe downstream consequences. | W12: Restrict access to the far-edge Kubernetes services to authenticated, least-privilege paths. | Y12: =IF(H12=Reference!$A$12, Reference!$C$12, IF(H12=Reference!$A$11, Reference!$C$11, IF(H12=Reference!$A$10, Reference!$C$10, IF(H12=Reference!$A$9, Reference!$C$9, 0)))) -> 4 | Z12: =IF(J12=Reference!$A$20, Reference!$C$20, IF(J12=Reference!$A$19, Reference!$C$19, IF(J12=Reference!$A$18, Reference!$C$18, IF(J12=Reference!$A$17, Reference!$C$17, 0)))) -> 10 | AA12: =IF(L12=Reference!$A$28, Reference!$C$28, IF(L12=Reference!$A$27, Reference!$C$27, IF(L12=Reference!$A$26, Reference!$C$26, IF(L12=Reference!$A$25, Reference!$C$25, 0)))) -> 7 | AB12: =IF(N12=Reference!$A$36, Reference!$C$36, IF(N12=Reference!$A$35, Reference!$C$35, IF(N12=Reference!$A$34, Reference!$C$34, IF(N12=Reference!$A$33, Reference!$C$33, 0)))) -> 7 | AC12: =(Reference!$B$2*Y12 + Reference!$B$3*AA12 + Reference!$B$4*Z12 + Reference!$B$5 * AB12)/4 -> 8.4375 | AD12: =IF(Q12=Reference!$C$41, Reference!$D$41, IF(Q12=Reference!$C$42, Reference!$D$42, IF(Q12=Reference!$C$43, Reference!$D$43, IF(Q12=Reference!$C$44, Reference!$D$44, 0)))) -> 7 | AE12: =1 + (AC12 * AD12) -> 60.0625
A13: 868 MHz LoRa air interface (OBU -> LoRa GW) | B13: Information disclosure | C13: Confidentiality | D13: Disclosure of a specific vehicle's trajectory and in-cabin exposure history -- a privacy breach for the driver/fleet and competitive-intelligence leakage for operators. Privacy / Financial. | E13: LoRaWAN session keys, if extracted from a compromised sensor unit or left at default/weak values, allow an eavesdropper within range to decrypt uplinks. | F13: Adjacent | G13: Decrypting uplinks requires RF range to the transmission plus either weak/default keys or physical key extraction from a node. | H13: Negligible | I13: No direct safety consequence from disclosure alone. | J13: Major | K13: Competitive-intelligence leakage of fleet trajectories carries significant financial impact for operators. | L13: Negligible | M13: No direct effect on vehicle function. | N13: Severe | O13: Location trajectory combined with in-cabin exposure history is highly sensitive and easily linked to a specific vehicle/driver. | P13: =IF(AC13>=Reference!$H$2, Reference!$G$2, IF(AC13>=Reference!$H$3, Reference!$G$3, IF(AC13>=Reference!$H$4, Reference!$G$4, IF(AC13>=Reference!$H$5, Reference!$G$5, "")))) -> Moderate | Q13: =IF(F13="Physical", "Very Low", IF(F13="Local", "Low", IF(F13="Adjacent", "Medium", IF(F13="Network", "High", "")))) -> Medium | R13: =IF(AE13>=Reference!$D$2, Reference!$G$2, IF(AE13>=Reference!$D$3, Reference!$E$3, IF(AE13>=Reference!$D$4, Reference!$E$4, IF(AE13>=Reference!$D$5, Reference!$E$5, "")))) -> Medium | S13: Mitigation | T13: Unique per-device LoRaWAN session keys (no defaults), secure key storage/provisioning, key rotation, OTAA activation instead of ABP. | U13: LoRaWAN session-key storage, OBU LoRa radio. | V13: Default/weak keys are the dominant root cause; enforcing per-device OTAA keys is a low-cost, high-value fix for a severe privacy risk. | W13: Ensure confidentiality of LoRaWAN uplink payloads via strong per-device keys. | Y13: =IF(H13=Reference!$A$12, Reference!$C$12, IF(H13=Reference!$A$11, Reference!$C$11, IF(H13=Reference!$A$10, Reference!$C$10, IF(H13=Reference!$A$9, Reference!$C$9, 0)))) -> 1 | Z13: =IF(J13=Reference!$A$20, Reference!$C$20, IF(J13=Reference!$A$19, Reference!$C$19, IF(J13=Reference!$A$18, Reference!$C$18, IF(J13=Reference!$A$17, Reference!$C$17, 0)))) -> 7 | AA13: =IF(L13=Reference!$A$28, Reference!$C$28, IF(L13=Reference!$A$27, Reference!$C$27, IF(L13=Reference!$A$26, Reference!$C$26, IF(L13=Reference!$A$25, Reference!$C$25, 0)))) -> 1 | AB13: =IF(N13=Reference!$A$36, Reference!$C$36, IF(N13=Reference!$A$35, Reference!$C$35, IF(N13=Reference!$A$34, Reference!$C$34, IF(N13=Reference!$A$33, Reference!$C$33, 0)))) -> 10 | AC13: =(Reference!$B$2*Y13 + Reference!$B$3*AA13 + Reference!$B$4*Z13 + Reference!$B$5 * AB13)/4 -> 3 | AD13: =IF(Q13=Reference!$C$41, Reference!$D$41, IF(Q13=Reference!$C$42, Reference!$D$42, IF(Q13=Reference!$C$43, Reference!$D$43, IF(Q13=Reference!$C$44, Reference!$D$44, 0)))) -> 7 | AE13: =1 + (AC13 * AD13) -> 22
A14: LoRaWAN uplink frame counter / MAC layer | B14: Spoofing | C14: Integrity | D14: Stale or attacker-controlled pollution/GPS data is accepted by the LoRaWAN server as genuine, corrupting the edge air-quality analysis and any short-term forecasts. Operational / Financial. | E14: Attacker captures valid encrypted uplink frames and re-transmits them later by abusing frame-counter reset/rollover behavior, or spoofs a device using a cloned DevEUI/AppEUI, impersonating a legitimate end-device to the network server. | F14: Adjacent | G14: Replay/spoofing requires RF range to capture or transmit LoRa frames but no physical access. | H14: Moderate | I14: Corrupted short-term forecasts could indirectly steer users toward polluted conditions. | J14: Moderate | K14: Data-quality issues degrade the dataset's commercial/analytic value. | L14: Major | M14: Edge air-quality analysis and forecasting integrity are directly undermined. | N14: Negligible | O14: No new PII exposure from replay/spoofing alone. | P14: =IF(AC14>=Reference!$H$2, Reference!$G$2, IF(AC14>=Reference!$H$3, Reference!$G$3, IF(AC14>=Reference!$H$4, Reference!$G$4, IF(AC14>=Reference!$H$5, Reference!$G$5, "")))) -> Major | Q14: =IF(F14="Physical", "Very Low", IF(F14="Local", "Low", IF(F14="Adjacent", "Medium", IF(F14="Network", "High", "")))) -> Medium | R14: =IF(AE14>=Reference!$D$2, Reference!$G$2, IF(AE14>=Reference!$D$3, Reference!$E$3, IF(AE14>=Reference!$D$4, Reference!$E$4, IF(AE14>=Reference!$D$5, Reference!$E$5, "")))) -> High | S14: Mitigation | T14: Strict frame-counter validation with anti-rollback, per-device unique keys to prevent DevEUI cloning, network-server replay detection. | U14: LoRaWAN network server, frame-counter validation logic. | V14: Standard LoRaWAN anti-replay mechanisms directly close this gap at low implementation cost. | W14: Ensure authenticity and freshness of LoRaWAN uplink frames. | Y14: =IF(H14=Reference!$A$12, Reference!$C$12, IF(H14=Reference!$A$11, Reference!$C$11, IF(H14=Reference!$A$10, Reference!$C$10, IF(H14=Reference!$A$9, Reference!$C$9, 0)))) -> 4 | Z14: =IF(J14=Reference!$A$20, Reference!$C$20, IF(J14=Reference!$A$19, Reference!$C$19, IF(J14=Reference!$A$18, Reference!$C$18, IF(J14=Reference!$A$17, Reference!$C$17, 0)))) -> 4 | AA14: =IF(L14=Reference!$A$28, Reference!$C$28, IF(L14=Reference!$A$27, Reference!$C$27, IF(L14=Reference!$A$26, Reference!$C$26, IF(L14=Reference!$A$25, Reference!$C$25, 0)))) -> 7 | AB14: =IF(N14=Reference!$A$36, Reference!$C$36, IF(N14=Reference!$A$35, Reference!$C$35, IF(N14=Reference!$A$34, Reference!$C$34, IF(N14=Reference!$A$33, Reference!$C$33, 0)))) -> 1 | AC14: =(Reference!$B$2*Y14 + Reference!$B$3*AA14 + Reference!$B$4*Z14 + Reference!$B$5 * AB14)/4 -> 7.3125 | AD14: =IF(Q14=Reference!$C$41, Reference!$D$41, IF(Q14=Reference!$C$42, Reference!$D$42, IF(Q14=Reference!$C$43, Reference!$D$43, IF(Q14=Reference!$C$44, Reference!$D$44, 0)))) -> 7 | AE14: =1 + (AC14 * AD14) -> 52.1875
... A34: IUC display-driver firmware/logic | B34: Denial of service | C34: Availability | D34: Occupants trust a frozen, outdated 'safe' reading indefinitely, with no fail-safe indication the monitoring function has failed. Safety. | E34: Resource exhaustion or a crafted malformed sensor frame from any upstream compromised node crashes or hangs the IUC main loop, freezing the display on its last rendered frame. | F34: Local | G34: A malformed frame from any already-compromised upstream node (sensor, WiFi, LoRa) can reach and crash the IUC's local processing loop. | H34: Severe | I34: An indefinitely frozen 'safe' display is functionally equivalent to a permanent false-safe indication, a severe safety risk. | J34: Moderate | K34: Liability exposure similar to ACT-01 if traced to this failure mode following an injury. | L34: Severe | M34: The IUC's main processing/display loop is completely disabled. | N34: Negligible | O34: No PII involved. | P34: =IF(AC34>=Reference!$H$2, Reference!$G$2, IF(AC34>=Reference!$H$3, Reference!$G$3, IF(AC34>=Reference!$H$4, Reference!$G$4, IF(AC34>=Reference!$H$5, Reference!$G$5, "")))) -> Severe | Q34: =IF(F34="Physical", "Very Low", IF(F34="Local", "Low", IF(F34="Adjacent", "Medium", IF(F34="Network", "High", "")))) -> Low | R34: =IF(AE34>=Reference!$D$2, Reference!$G$2, IF(AE34>=Reference!$D$3, Reference!$E$3, IF(AE34>=Reference!$D$4, Reference!$E$4, IF(AE34>=Reference!$D$5, Reference!$E$5, "")))) -> High | S34: Mitigation | T34: Robust input parsing/validation with fuzz-tested frame handling, watchdog timer forcing a visible fail-safe state (not last-good-frame) on hang/crash, rate-limiting of inbound frames. | U34: IUC main loop, display-driver firmware. | V34: A watchdog-triggered fail-safe display state directly closes the gap between 'crashed' and 'silently trusted as safe'. | W34: Ensure the Status Display fails visibly and safely rather than freezing on a stale 'safe' reading. | Y34: =IF(H34=Reference!$A$12, Reference!$C$12, IF(H34=Reference!$A$11, Reference!$C$11, IF(H34=Reference!$A$10, Reference!$C$10, IF(H34=Reference!$A$9, Reference!$C$9, 0)))) -> 10 | Z34: =IF(J34=Reference!$A$20, Reference!$C$20, IF(J34=Reference!$A$19, Reference!$C$19, IF(J34=Reference!$A$18, Reference!$C$18, IF(J34=Reference!$A$17, Reference!$C$17, 0)))) -> 4 | AA34: =IF(L34=Reference!$A$28, Reference!$C$28, IF(L34=Reference!$A$27, Reference!$C$27, IF(L34=Reference!$A$26, Reference!$C$26, IF(L34=Reference!$A$25, Reference!$C$25, 0)))) -> 10 | AB34: =IF(N34=Reference!$A$36, Reference!$C$36, IF(N34=Reference!$A$35, Reference!$C$35, IF(N34=Reference!$A$34, Reference!$C$34, IF(N34=Reference!$A$33, Reference!$C$33, 0)))) -> 1 | AC34: =(Reference!$B$2*Y34 + Reference!$B$3*AA34 + Reference!$B$4*Z34 + Reference!$B$5 * AB34)/4 -> 15.5625 | AD34: =IF(Q34=Reference!$C$41, Reference!$D$41, IF(Q34=Reference!$C$42, Reference!$D$42, IF(Q34=Reference!$C$43, Reference!$D$43, IF(Q34=Reference!$C$44, Reference!$D$44, 0)))) -> 4 | AE34: =1 + (AC34 * AD34) -> 63.25
P35: =IF(AC35>=Reference!$H$2, Reference!$G$2, IF(AC35>=Reference!$H$3, Reference!$G$3, IF(AC35>=Reference!$H$4, Reference!$G$4, IF(AC35>=Reference!$H$5, Reference!$G$5, "")))) | Q35: =IF(F35="Physical", "Very Low", IF(F35="Local", "Low", IF(F35="Adjacent", "Medium", IF(F35="Network", "High", "")))) | R35: =IF(AE35>=Reference!$D$2, Reference!$G$2, IF(AE35>=Reference!$D$3, Reference!$E$3, IF(AE35>=Reference!$D$4, Reference!$E$4, IF(AE35>=Reference!$D$5, Reference!$E$5, "")))) -> Low | Y35: =IF(H35=Reference!$A$12, Reference!$C$12, IF(H35=Reference!$A$11, Reference!$C$11, IF(H35=Reference!$A$10, Reference!$C$10, IF(H35=Reference!$A$9, Reference!$C$9, 0)))) -> 0 | Z35: =IF(J35=Reference!$A$20, Reference!$C$20, IF(J35=Reference!$A$19, Reference!$C$19, IF(J35=Reference!$A$18, Reference!$C$18, IF(J35=Reference!$A$17, Reference!$C$17, 0)))) -> 0 | AA35: =IF(L35=Reference!$A$28, Reference!$C$28, IF(L35=Reference!$A$27, Reference!$C$27, IF(L35=Reference!$A$26, Reference!$C$26, IF(L35=Reference!$A$25, Reference!$C$25, 0)))) -> 0 | AB35: =IF(N35=Reference!$A$36, Reference!$C$36, IF(N35=Reference!$A$35, Reference!$C$35, IF(N35=Reference!$A$34, Reference!$C$34, IF(N35=Reference!$A$33, Reference!$C$33, 0)))) -> 0 | AC35: =(Reference!$B$2*Y35 + Reference!$B$3*AA35 + Reference!$B$4*Z35 + Reference!$B$5 * AB35)/4 -> 0 | AD35: =IF(Q35=Reference!$C$41, Reference!$D$41, IF(Q35=Reference!$C$42, Reference!$D$42, IF(Q35=Reference!$C$43, Reference!$D$43, IF(Q35=Reference!$C$44, Reference!$D$44, 0)))) -> 0 | AE35: =1 + (AC35 * AD35) -> 1
P36: =IF(AC36>=Reference!$H$2, Reference!$G$2, IF(AC36>=Reference!$H$3, Reference!$G$3, IF(AC36>=Reference!$H$4, Reference!$G$4, IF(AC36>=Reference!$H$5, Reference!$G$5, "")))) | Q36: =IF(F36="Physical", "Very Low", IF(F36="Local", "Low", IF(F36="Adjacent", "Medium", IF(F36="Network", "High", "")))) | R36: =IF(AE36>=Reference!$D$2, Reference!$G$2, IF(AE36>=Reference!$D$3, Reference!$E$3, IF(AE36>=Reference!$D$4, Reference!$E$4, IF(AE36>=Reference!$D$5, Reference!$E$5, "")))) -> Low | Y36: =IF(H36=Reference!$A$12, Reference!$C$12, IF(H36=Reference!$A$11, Reference!$C$11, IF(H36=Reference!$A$10, Reference!$C$10, IF(H36=Reference!$A$9, Reference!$C$9, 0)))) -> 0 | Z36: =IF(J36=Reference!$A$20, Reference!$C$20, IF(J36=Reference!$A$19, Reference!$C$19, IF(J36=Reference!$A$18, Reference!$C$18, IF(J36=Reference!$A$17, Reference!$C$17, 0)))) -> 0 | AA36: =IF(L36=Reference!$A$28, Reference!$C$28, IF(L36=Reference!$A$27, Reference!$C$27, IF(L36=Reference!$A$26, Reference!$C$26, IF(L36=Reference!$A$25, Reference!$C$25, 0)))) -> 0 | AB36: =IF(N36=Reference!$A$36, Reference!$C$36, IF(N36=Reference!$A$35, Reference!$C$35, IF(N36=Reference!$A$34, Reference!$C$34, IF(N36=Reference!$A$33, Reference!$C$33, 0)))) -> 0 | AC36: =(Reference!$B$2*Y36 + Reference!$B$3*AA36 + Reference!$B$4*Z36 + Reference!$B$5 * AB36)/4 -> 0 | AD36: =IF(Q36=Reference!$C$41, Reference!$D$41, IF(Q36=Reference!$C$42, Reference!$D$42, IF(Q36=Reference!$C$43, Reference!$D$43, IF(Q36=Reference!$C$44, Reference!$D$44, 0)))) -> 0 | AE36: =1 + (AC36 * AD36) -> 1
P37: =IF(AC37>=Reference!$H$2, Reference!$G$2, IF(AC37>=Reference!$H$3, Reference!$G$3, IF(AC37>=Reference!$H$4, Reference!$G$4, IF(AC37>=Reference!$H$5, Reference!$G$5, "")))) | Q37: =IF(F37="Physical", "Very Low", IF(F37="Local", "Low", IF(F37="Adjacent", "Medium", IF(F37="Network", "High", "")))) | R37: =IF(AE37>=Reference!$D$2, Reference!$G$2, IF(AE37>=Reference!$D$3, Reference!$E$3, IF(AE37>=Reference!$D$4, Reference!$E$4, IF(AE37>=Reference!$D$5, Reference!$E$5, "")))) -> Low | Y37: =IF(H37=Reference!$A$12, Reference!$C$12, IF(H37=Reference!$A$11, Reference!$C$11, IF(H37=Reference!$A$10, Reference!$C$10, IF(H37=Reference!$A$9, Reference!$C$9, 0)))) -> 0 | Z37: =IF(J37=Reference!$A$20, Reference!$C$20, IF(J37=Reference!$A$19, Reference!$C$19, IF(J37=Reference!$A$18, Reference!$C$18, IF(J37=Reference!$A$17, Reference!$C$17, 0)))) -> 0 | AA37: =IF(L37=Reference!$A$28, Reference!$C$28, IF(L37=Reference!$A$27, Reference!$C$27, IF(L37=Reference!$A$26, Reference!$C$26, IF(L37=Reference!$A$25, Reference!$C$25, 0)))) -> 0 | AB37: =IF(N37=Reference!$A$36, Reference!$C$36, IF(N37=Reference!$A$35, Reference!$C$35, IF(N37=Reference!$A$34, Reference!$C$34, IF(N37=Reference!$A$33, Reference!$C$33, 0)))) -> 0 | AC37: =(Reference!$B$2*Y37 + Reference!$B$3*AA37 + Reference!$B$4*Z37 + Reference!$B$5 * AB37)/4 -> 0 | AD37: =IF(Q37=Reference!$C$41, Reference!$D$41, IF(Q37=Reference!$C$42, Reference!$D$42, IF(Q37=Reference!$C$43, Reference!$D$43, IF(Q37=Reference!$C$44, Reference!$D$44, 0)))) -> 0 | AE37: =1 + (AC37 * AD37) -> 1
P38: =IF(AC38>=Reference!$H$2, Reference!$G$2, IF(AC38>=Reference!$H$3, Reference!$G$3, IF(AC38>=Reference!$H$4, Reference!$G$4, IF(AC38>=Reference!$H$5, Reference!$G$5, "")))) | Q38: =IF(F38="Physical", "Very Low", IF(F38="Local", "Low", IF(F38="Adjacent", "Medium", IF(F38="Network", "High", "")))) | R38: =IF(AE38>=Reference!$D$2, Reference!$G$2, IF(AE38>=Reference!$D$3, Reference!$E$3, IF(AE38>=Reference!$D$4, Reference!$E$4, IF(AE38>=Reference!$D$5, Reference!$E$5, "")))) -> Low | Y38: =IF(H38=Reference!$A$12, Reference!$C$12, IF(H38=Reference!$A$11, Reference!$C$11, IF(H38=Reference!$A$10, Reference!$C$10, IF(H38=Reference!$A$9, Reference!$C$9, 0)))) -> 0 | Z38: =IF(J38=Reference!$A$20, Reference!$C$20, IF(J38=Reference!$A$19, Reference!$C$19, IF(J38=Reference!$A$18, Reference!$C$18, IF(J38=Reference!$A$17, Reference!$C$17, 0)))) -> 0 | AA38: =IF(L38=Reference!$A$28, Reference!$C$28, IF(L38=Reference!$A$27, Reference!$C$27, IF(L38=Reference!$A$26, Reference!$C$26, IF(L38=Reference!$A$25, Reference!$C$25, 0)))) -> 0 | AB38: =IF(N38=Reference!$A$36, Reference!$C$36, IF(N38=Reference!$A$35, Reference!$C$35, IF(N38=Reference!$A$34, Reference!$C$34, IF(N38=Reference!$A$33, Reference!$C$33, 0)))) -> 0 | AC38: =(Reference!$B$2*Y38 + Reference!$B$3*AA38 + Reference!$B$4*Z38 + Reference!$B$5 * AB38)/4 -> 0 | AD38: =IF(Q38=Reference!$C$41, Reference!$D$41, IF(Q38=Reference!$C$42, Reference!$D$42, IF(Q38=Reference!$C$43, Reference!$D$43, IF(Q38=Reference!$C$44, Reference!$D$44, 0)))) -> 0 | AE38: =1 + (AC38 * AD38) -> 1
P39: =IF(AC39>=Reference!$H$2, Reference!$G$2, IF(AC39>=Reference!$H$3, Reference!$G$3, IF(AC39>=Reference!$H$4, Reference!$G$4, IF(AC39>=Reference!$H$5, Reference!$G$5, "")))) | Q39: =IF(F39="Physical", "Very Low", IF(F39="Local", "Low", IF(F39="Adjacent", "Medium", IF(F39="Network", "High", "")))) | R39: =IF(AE39>=Reference!$D$2, Reference!$G$2, IF(AE39>=Reference!$D$3, Reference!$E$3, IF(AE39>=Reference!$D$4, Reference!$E$4, IF(AE39>=Reference!$D$5, Reference!$E$5, "")))) -> Low | Y39: =IF(H39=Reference!$A$12, Reference!$C$12, IF(H39=Reference!$A$11, Reference!$C$11, IF(H39=Reference!$A$10, Reference!$C$10, IF(H39=Reference!$A$9, Reference!$C$9, 0)))) -> 0 | Z39: =IF(J39=Reference!$A$20, Reference!$C$20, IF(J39=Reference!$A$19, Reference!$C$19, IF(J39=Reference!$A$18, Reference!$C$18, IF(J39=Reference!$A$17, Reference!$C$17, 0)))) -> 0 | AA39: =IF(L39=Reference!$A$28, Reference!$C$28, IF(L39=Reference!$A$27, Reference!$C$27, IF(L39=Reference!$A$26, Reference!$C$26, IF(L39=Reference!$A$25, Reference!$C$25, 0)))) -> 0 | AB39: =IF(N39=Reference!$A$36, Reference!$C$36, IF(N39=Reference!$A$35, Reference!$C$35, IF(N39=Reference!$A$34, Reference!$C$34, IF(N39=Reference!$A$33, Reference!$C$33, 0)))) -> 0 | AC39: =(Reference!$B$2*Y39 + Reference!$B$3*AA39 + Reference!$B$4*Z39 + Reference!$B$5 * AB39)/4 -> 0 | AD39: =IF(Q39=Reference!$C$41, Reference!$D$41, IF(Q39=Reference!$C$42, Reference!$D$42, IF(Q39=Reference!$C$43, Reference!$D$43, IF(Q39=Reference!$C$44, Reference!$D$44, 0)))) -> 0 | AE39: =1 + (AC39 * AD39) -> 1
P40: =IF(AC40>=Reference!$H$2, Reference!$G$2, IF(AC40>=Reference!$H$3, Reference!$G$3, IF(AC40>=Reference!$H$4, Reference!$G$4, IF(AC40>=Reference!$H$5, Reference!$G$5, "")))) | Q40: =IF(F40="Physical", "Very Low", IF(F40="Local", "Low", IF(F40="Adjacent", "Medium", IF(F40="Network", "High", "")))) | R40: =IF(AE40>=Reference!$D$2, Reference!$G$2, IF(AE40>=Reference!$D$3, Reference!$E$3, IF(AE40>=Reference!$D$4, Reference!$E$4, IF(AE40>=Reference!$D$5, Reference!$E$5, "")))) -> Low | Y40: =IF(H40=Reference!$A$12, Reference!$C$12, IF(H40=Reference!$A$11, Reference!$C$11, IF(H40=Reference!$A$10, Reference!$C$10, IF(H40=Reference!$A$9, Reference!$C$9, 0)))) -> 0 | Z40: =IF(J40=Reference!$A$20, Reference!$C$20, IF(J40=Reference!$A$19, Reference!$C$19, IF(J40=Reference!$A$18, Reference!$C$18, IF(J40=Reference!$A$17, Reference!$C$17, 0)))) -> 0 | AA40: =IF(L40=Reference!$A$28, Reference!$C$28, IF(L40=Reference!$A$27, Reference!$C$27, IF(L40=Reference!$A$26, Reference!$C$26, IF(L40=Reference!$A$25, Reference!$C$25, 0)))) -> 0 | AB40: =IF(N40=Reference!$A$36, Reference!$C$36, IF(N40=Reference!$A$35, Reference!$C$35, IF(N40=Reference!$A$34, Reference!$C$34, IF(N40=Reference!$A$33, Reference!$C$33, 0)))) -> 0 | AC40: =(Reference!$B$2*Y40 + Reference!$B$3*AA40 + Reference!$B$4*Z40 + Reference!$B$5 * AB40)/4 -> 0 | AD40: =IF(Q40=Reference!$C$41, Reference!$D$41, IF(Q40=Reference!$C$42, Reference!$D$42, IF(Q40=Reference!$C$43, Reference!$D$43, IF(Q40=Reference!$C$44, Reference!$D$44, 0)))) -> 0 | AE40: =1 + (AC40 * AD40) -> 1
P41: =IF(AC41>=Reference!$H$2, Reference!$G$2, IF(AC41>=Reference!$H$3, Reference!$G$3, IF(AC41>=Reference!$H$4, Reference!$G$4, IF(AC41>=Reference!$H$5, Reference!$G$5, "")))) | Q41: =IF(F41="Physical", "Very Low", IF(F41="Local", "Low", IF(F41="Adjacent", "Medium", IF(F41="Network", "High", "")))) | R41: =IF(AE41>=Reference!$D$2, Reference!$G$2, IF(AE41>=Reference!$D$3, Reference!$E$3, IF(AE41>=Reference!$D$4, Reference!$E$4, IF(AE41>=Reference!$D$5, Reference!$E$5, "")))) -> Low | Y41: =IF(H41=Reference!$A$12, Reference!$C$12, IF(H41=Reference!$A$11, Reference!$C$11, IF(H41=Reference!$A$10, Reference!$C$10, IF(H41=Reference!$A$9, Reference!$C$9, 0)))) -> 0 | Z41: =IF(J41=Reference!$A$20, Reference!$C$20, IF(J41=Reference!$A$19, Reference!$C$19, IF(J41=Reference!$A$18, Reference!$C$18, IF(J41=Reference!$A$17, Reference!$C$17, 0)))) -> 0 | AA41: =IF(L41=Reference!$A$28, Reference!$C$28, IF(L41=Reference!$A$27, Reference!$C$27, IF(L41=Reference!$A$26, Reference!$C$26, IF(L41=Reference!$A$25, Reference!$C$25, 0)))) -> 0 | AB41: =IF(N41=Reference!$A$36, Reference!$C$36, IF(N41=Reference!$A$35, Reference!$C$35, IF(N41=Reference!$A$34, Reference!$C$34, IF(N41=Reference!$A$33, Reference!$C$33, 0)))) -> 0 | AC41: =(Reference!$B$2*Y41 + Reference!$B$3*AA41 + Reference!$B$4*Z41 + Reference!$B$5 * AB41)/4 -> 0 | AD41: =IF(Q41=Reference!$C$41, Reference!$D$41, IF(Q41=Reference!$C$42, Reference!$D$42, IF(Q41=Reference!$C$43, Reference!$D$43, IF(Q41=Reference!$C$44, Reference!$D$44, 0)))) -> 0 | AE41: =1 + (AC41 * AD41) -> 1
P42: =IF(AC42>=Reference!$H$2, Reference!$G$2, IF(AC42>=Reference!$H$3, Reference!$G$3, IF(AC42>=Reference!$H$4, Reference!$G$4, IF(AC42>=Reference!$H$5, Reference!$G$5, "")))) | Q42: =IF(F42="Physical", "Very Low", IF(F42="Local", "Low", IF(F42="Adjacent", "Medium", IF(F42="Network", "High", "")))) | R42: =IF(AE42>=Reference!$D$2, Reference!$G$2, IF(AE42>=Reference!$D$3, Reference!$E$3, IF(AE42>=Reference!$D$4, Reference!$E$4, IF(AE42>=Reference!$D$5, Reference!$E$5, "")))) -> Low | Y42: =IF(H42=Reference!$A$12, Reference!$C$12, IF(H42=Reference!$A$11, Reference!$C$11, IF(H42=Reference!$A$10, Reference!$C$10, IF(H42=Reference!$A$9, Reference!$C$9, 0)))) -> 0 | Z42: =IF(J42=Reference!$A$20, Reference!$C$20, IF(J42=Reference!$A$19, Reference!$C$19, IF(J42=Reference!$A$18, Reference!$C$18, IF(J42=Reference!$A$17, Reference!$C$17, 0)))) -> 0 | AA42: =IF(L42=Reference!$A$28, Reference!$C$28, IF(L42=Reference!$A$27, Reference!$C$27, IF(L42=Reference!$A$26, Reference!$C$26, IF(L42=Reference!$A$25, Reference!$C$25, 0)))) -> 0 | AB42: =IF(N42=Reference!$A$36, Reference!$C$36, IF(N42=Reference!$A$35, Reference!$C$35, IF(N42=Reference!$A$34, Reference!$C$34, IF(N42=Reference!$A$33, Reference!$C$33, 0)))) -> 0 | AC42: =(Reference!$B$2*Y42 + Reference!$B$3*AA42 + Reference!$B$4*Z42 + Reference!$B$5 * AB42)/4 -> 0 | AD42: =IF(Q42=Reference!$C$41, Reference!$D$41, IF(Q42=Reference!$C$42, Reference!$D$42, IF(Q42=Reference!$C$43, Reference!$D$43, IF(Q42=Reference!$C$44, Reference!$D$44, 0)))) -> 0 | AE42: =1 + (AC42 * AD42) -> 1
P43: =IF(AC43>=Reference!$H$2, Reference!$G$2, IF(AC43>=Reference!$H$3, Reference!$G$3, IF(AC43>=Reference!$H$4, Reference!$G$4, IF(AC43>=Reference!$H$5, Reference!$G$5, "")))) | Q43: =IF(F43="Physical", "Very Low", IF(F43="Local", "Low", IF(F43="Adjacent", "Medium", IF(F43="Network", "High", "")))) | R43: =IF(AE43>=Reference!$D$2, Reference!$G$2, IF(AE43>=Reference!$D$3, Reference!$E$3, IF(AE43>=Reference!$D$4, Reference!$E$4, IF(AE43>=Reference!$D$5, Reference!$E$5, "")))) -> Low | Y43: =IF(H43=Reference!$A$12, Reference!$C$12, IF(H43=Reference!$A$11, Reference!$C$11, IF(H43=Reference!$A$10, Reference!$C$10, IF(H43=Reference!$A$9, Reference!$C$9, 0)))) -> 0 | Z43: =IF(J43=Reference!$A$20, Reference!$C$20, IF(J43=Reference!$A$19, Reference!$C$19, IF(J43=Reference!$A$18, Reference!$C$18, IF(J43=Reference!$A$17, Reference!$C$17, 0)))) -> 0 | AA43: =IF(L43=Reference!$A$28, Reference!$C$28, IF(L43=Reference!$A$27, Reference!$C$27, IF(L43=Reference!$A$26, Reference!$C$26, IF(L43=Reference!$A$25, Reference!$C$25, 0)))) -> 0 | AB43: =IF(N43=Reference!$A$36, Reference!$C$36, IF(N43=Reference!$A$35, Reference!$C$35, IF(N43=Reference!$A$34, Reference!$C$34, IF(N43=Reference!$A$33, Reference!$C$33, 0)))) -> 0 | AC43: =(Reference!$B$2*Y43 + Reference!$B$3*AA43 + Reference!$B$4*Z43 + Reference!$B$5 * AB43)/4 -> 0 | AD43: =IF(Q43=Reference!$C$41, Reference!$D$41, IF(Q43=Reference!$C$42, Reference!$D$42, IF(Q43=Reference!$C$43, Reference!$D$43, IF(Q43=Reference!$C$44, Reference!$D$44, 0)))) -> 0 | AE43: =1 + (AC43 * AD43) -> 1
P44: =IF(AC44>=Reference!$H$2, Reference!$G$2, IF(AC44>=Reference!$H$3, Reference!$G$3, IF(AC44>=Reference!$H$4, Reference!$G$4, IF(AC44>=Reference!$H$5, Reference!$G$5, "")))) | Q44: =IF(F44="Physical", "Very Low", IF(F44="Local", "Low", IF(F44="Adjacent", "Medium", IF(F44="Network", "High", "")))) | R44: =IF(AE44>=Reference!$D$2, Reference!$G$2, IF(AE44>=Reference!$D$3, Reference!$E$3, IF(AE44>=Reference!$D$4, Reference!$E$4, IF(AE44>=Reference!$D$5, Reference!$E$5, "")))) -> Low | Y44: =IF(H44=Reference!$A$12, Reference!$C$12, IF(H44=Reference!$A$11, Reference!$C$11, IF(H44=Reference!$A$10, Reference!$C$10, IF(H44=Reference!$A$9, Reference!$C$9, 0)))) -> 0 | Z44: =IF(J44=Reference!$A$20, Reference!$C$20, IF(J44=Reference!$A$19, Reference!$C$19, IF(J44=Reference!$A$18, Reference!$C$18, IF(J44=Reference!$A$17, Reference!$C$17, 0)))) -> 0 | AA44: =IF(L44=Reference!$A$28, Reference!$C$28, IF(L44=Reference!$A$27, Reference!$C$27, IF(L44=Reference!$A$26, Reference!$C$26, IF(L44=Reference!$A$25, Reference!$C$25, 0)))) -> 0 | AB44: =IF(N44=Reference!$A$36, Reference!$C$36, IF(N44=Reference!$A$35, Reference!$C$35, IF(N44=Reference!$A$34, Reference!$C$34, IF(N44=Reference!$A$33, Reference!$C$33, 0)))) -> 0 | AC44: =(Reference!$B$2*Y44 + Reference!$B$3*AA44 + Reference!$B$4*Z44 + Reference!$B$5 * AB44)/4 -> 0 | AD44: =IF(Q44=Reference!$C$41, Reference!$D$41, IF(Q44=Reference!$C$42, Reference!$D$42, IF(Q44=Reference!$C$43, Reference!$D$43, IF(Q44=Reference!$C$44, Reference!$D$44, 0)))) -> 0 | AE44: =1 + (AC44 * AD44) -> 1
P45: =IF(AC45>=Reference!$H$2, Reference!$G$2, IF(AC45>=Reference!$H$3, Reference!$G$3, IF(AC45>=Reference!$H$4, Reference!$G$4, IF(AC45>=Reference!$H$5, Reference!$G$5, "")))) | Q45: =IF(F45="Physical", "Very Low", IF(F45="Local", "Low", IF(F45="Adjacent", "Medium", IF(F45="Network", "High", "")))) | R45: =IF(AE45>=Reference!$D$2, Reference!$G$2, IF(AE45>=Reference!$D$3, Reference!$E$3, IF(AE45>=Reference!$D$4, Reference!$E$4, IF(AE45>=Reference!$D$5, Reference!$E$5, "")))) -> Low | Y45: =IF(H45=Reference!$A$12, Reference!$C$12, IF(H45=Reference!$A$11, Reference!$C$11, IF(H45=Reference!$A$10, Reference!$C$10, IF(H45=Reference!$A$9, Reference!$C$9, 0)))) -> 0 | Z45: =IF(J45=Reference!$A$20, Reference!$C$20, IF(J45=Reference!$A$19, Reference!$C$19, IF(J45=Reference!$A$18, Reference!$C$18, IF(J45=Reference!$A$17, Reference!$C$17, 0)))) -> 0 | AA45: =IF(L45=Reference!$A$28, Reference!$C$28, IF(L45=Reference!$A$27, Reference!$C$27, IF(L45=Reference!$A$26, Reference!$C$26, IF(L45=Reference!$A$25, Reference!$C$25, 0)))) -> 0 | AB45: =IF(N45=Reference!$A$36, Reference!$C$36, IF(N45=Reference!$A$35, Reference!$C$35, IF(N45=Reference!$A$34, Reference!$C$34, IF(N45=Reference!$A$33, Reference!$C$33, 0)))) -> 0 | AC45: =(Reference!$B$2*Y45 + Reference!$B$3*AA45 + Reference!$B$4*Z45 + Reference!$B$5 * AB45)/4 -> 0 | AD45: =IF(Q45=Reference!$C$41, Reference!$D$41, IF(Q45=Reference!$C$42, Reference!$D$42, IF(Q45=Reference!$C$43, Reference!$D$43, IF(Q45=Reference!$C$44, Reference!$D$44, 0)))) -> 0 | AE45: =1 + (AC45 * AD45) -> 1
